Workbook
Name NUMSEM: DATOS!$A:$A
Name productos: Productos!$A:$A

Sheet Resumen
B2: FILTRO SEMANA | C2: 40 | L2: PRODUCTOS | M2: LUNES | N2: MARTES | O2: MIÉRCOLES | P2: JUEVES | Q2: VIERNES | R2: SÁBADO | S2: DOMINGO | T2: TOTAL
L3: =IFERROR(__xludf.DUMMYFUNCTION("UNIQUE(FILTER(Eventos!F:F,Eventos!D:D=C2))"),"#N/A") -> #N/A | M3: =SUMIFS(Eventos!$G:$G,Eventos!$F:$F,$L3,Eventos!$D:$D,$C$2,Eventos!$B:$B,PANES_SEMANALES[[#ALL],[LUNES]]) -> 0 | N3: =SUMIFS(Eventos!$G:$G,Eventos!$F:$F,$L3,Eventos!$D:$D,$C$2,Eventos!$B:$B,PANES_SEMANALES[[#ALL],[MARTES]]) -> 0 | O3: =SUMIFS(Eventos!$G:$G,Eventos!$F:$F,$L3,Eventos!$D:$D,$C$2,Eventos!$B:$B,PANES_SEMANALES[[#ALL],[MIÉRCOLES]]) -> 0 | P3: =SUMIFS(Eventos!$G:$G,Eventos!$F:$F,$L3,Eventos!$D:$D,$C$2,Eventos!$B:$B,PANES_SEMANALES[[#ALL],[JUEVES]]) -> 0 | Q3: =SUMIFS(Eventos!$G:$G,Eventos!$F:$F,$L3,Eventos!$D:$D,$C$2,Eventos!$B:$B,PANES_SEMANALES[[#ALL],[VIERNES]]) -> 0 | R3: =SUMIFS(Eventos!$G:$G,Eventos!$F:$F,$L3,Eventos!$D:$D,$C$2,Eventos!$B:$B,PANES_SEMANALES[[#ALL],[SÁBADO]]) -> 0 | S3: =SUMIFS(Eventos!$G:$G,Eventos!$F:$F,$L3,Eventos!$D:$D,$C$2,Eventos!$B:$B,PANES_SEMANALES[[#ALL],[DOMINGO]]) -> 0 | T3: =SUM(M3:S3) -> 0
M4: =SUMIFS(Eventos!$G:$G,Eventos!$F:$F,$L4,Eventos!$D:$D,$C$2,Eventos!$B:$B,PANES_SEMANALES[[#ALL],[LUNES]]) -> 0 | N4: =SUMIFS(Eventos!$G:$G,Eventos!$F:$F,$L4,Eventos!$D:$D,$C$2,Eventos!$B:$B,PANES_SEMANALES[[#ALL],[MARTES]]) -> 0 | O4: =SUMIFS(Eventos!$G:$G,Eventos!$F:$F,$L4,Eventos!$D:$D,$C$2,Eventos!$B:$B,PANES_SEMANALES[[#ALL],[MIÉRCOLES]]) -> 0 | P4: =SUMIFS(Eventos!$G:$G,Eventos!$F:$F,$L4,Eventos!$D:$D,$C$2,Eventos!$B:$B,PANES_SEMANALES[[#ALL],[JUEVES]]) -> 0 | Q4: =SUMIFS(Eventos!$G:$G,Eventos!$F:$F,$L4,Eventos!$D:$D,$C$2,Eventos!$B:$B,PANES_SEMANALES[[#ALL],[VIERNES]]) -> 0 | R4: =SUMIFS(Eventos!$G:$G,Eventos!$F:$F,$L4,Eventos!$D:$D,$C$2,Eventos!$B:$B,PANES_SEMANALES[[#ALL],[SÁBADO]]) -> 0 | S4: =SUMIFS(Eventos!$G:$G,Eventos!$F:$F,$L4,Eventos!$D:$D,$C$2,Eventos!$B:$B,PANES_SEMANALES[[#ALL],[DOMINGO]]) -> 0 | T4: =SUM(M4:S4) -> 0
B5: RESUMEN PAN SEMANAL | C5: LUNES | D5: MARTES | E5: MIÉRCOLES | F5: JUEVES | G5: VIERNES | H5: SÁBADO | I5: DOMINGO | J5: TOTAL | M5: =SUMIFS(Eventos!$G:$G,Eventos!$F:$F,$L5,Eventos!$D:$D,$C$2,Eventos!$B:$B,PANES_SEMANALES[[#ALL],[LUNES]]) -> 0 | N5: =SUMIFS(Eventos!$G:$G,Eventos!$F:$F,$L5,Eventos!$D:$D,$C$2,Eventos!$B:$B,PANES_SEMANALES[[#ALL],[MARTES]]) -> 0 | O5: =SUMIFS(Eventos!$G:$G,Eventos!$F:$F,$L5,Eventos!$D:$D,$C$2,Eventos!$B:$B,PANES_SEMANALES[[#ALL],[MIÉRCOLES]]) -> 0 | P5: =SUMIFS(Eventos!$G:$G,Eventos!$F:$F,$L5,Eventos!$D:$D,$C$2,Eventos!$B:$B,PANES_SEMANALES[[#ALL],[JUEVES]]) -> 0 | Q5: =SUMIFS(Eventos!$G:$G,Eventos!$F:$F,$L5,Eventos!$D:$D,$C$2,Eventos!$B:$B,PANES_SEMANALES[[#ALL],[VIERNES]]) -> 0 | R5: =SUMIFS(Eventos!$G:$G,Eventos!$F:$F,$L5,Eventos!$D:$D,$C$2,Eventos!$B:$B,PANES_SEMANALES[[#ALL],[SÁBADO]]) -> 0 | S5: =SUMIFS(Eventos!$G:$G,Eventos!$F:$F,$L5,Eventos!$D:$D,$C$2,Eventos!$B:$B,PANES_SEMANALES[[#ALL],[DOMINGO]]) -> 0 | T5: =SUM(M5:S5) -> 0
A6: {=SEQUENCE(COUNTA(B6:B28),1)} -> 1 | B6: =IFERROR(__xludf.DUMMYFUNCTION("SORT(UNIQUE(FILTER(Eventos!I:I,Eventos!D:D=C2)),1,TRUE)"),"#N/A") -> #N/A | C6: =SUMIFS(Eventos!$J:$J,Eventos!$I:$I,$B6,Eventos!$B:$B,C$5,Eventos!$D:$D,$C$2) -> 0 | D6: =SUMIFS(Eventos!$J:$J,Eventos!$I:$I,$B6,Eventos!$B:$B,D$5,Eventos!$D:$D,$C$2) -> 0 | E6: =SUMIFS(Eventos!$J:$J,Eventos!$I:$I,$B6,Eventos!$B:$B,E$5,Eventos!$D:$D,$C$2) -> 0 | F6: =SUMIFS(Eventos!$J:$J,Eventos!$I:$I,$B6,Eventos!$B:$B,F$5,Eventos!$D:$D,$C$2) -> 0 | G6: =SUMIFS(Eventos!$J:$J,Eventos!$I:$I,$B6,Eventos!$B:$B,G$5,Eventos!$D:$D,$C$2) -> 0 | H6: =SUMIFS(Eventos!$J:$J,Eventos!$I:$I,$B6,Eventos!$B:$B,H$5,Eventos!$D:$D,$C$2) -> 0 | I6: =SUMIFS(Eventos!$J:$J,Eventos!$I:$I,$B6,Eventos!$B:$B,I$5,Eventos!$D:$D,$C$2) -> 0 | J6: =SUM(C6:I6) -> 0 | M6: =SUMIFS(Eventos!$G:$G,Eventos!$F:$F,$L6,Eventos!$D:$D,$C$2,Eventos!$B:$B,PANES_SEMANALES[[#ALL],[LUNES]]) -> 0 | N6: =SUMIFS(Eventos!$G:$G,Eventos!$F:$F,$L6,Eventos!$D:$D,$C$2,Eventos!$B:$B,PANES_SEMANALES[[#ALL],[MARTES]]) -> 0 | O6: =SUMIFS(Eventos!$G:$G,Eventos!$F:$F,$L6,Eventos!$D:$D,$C$2,Eventos!$B:$B,PANES_SEMANALES[[#ALL],[MIÉRCOLES]]) -> 0 | P6: =SUMIFS(Eventos!$G:$G,Eventos!$F:$F,$L6,Eventos!$D:$D,$C$2,Eventos!$B:$B,PANES_SEMANALES[[#ALL],[JUEVES]]) -> 0 | Q6: =SUMIFS(Eventos!$G:$G,Eventos!$F:$F,$L6,Eventos!$D:$D,$C$2,Eventos!$B:$B,PANES_SEMANALES[[#ALL],[VIERNES]]) -> 0 | R6: =SUMIFS(Eventos!$G:$G,Eventos!$F:$F,$L6,Eventos!$D:$D,$C$2,Eventos!$B:$B,PANES_SEMANALES[[#ALL],[SÁBADO]]) -> 0 | S6: =SUMIFS(Eventos!$G:$G,Eventos!$F:$F,$L6,Eventos!$D:$D,$C$2,Eventos!$B:$B,PANES_SEMANALES[[#ALL],[DOMINGO]]) -> 0 | T6: =SUM(M6:S6) -> 0
C7: =SUMIFS(Eventos!$J:$J,Eventos!$I:$I,$B7,Eventos!$B:$B,C$5,Eventos!$D:$D,$C$2) -> 0 | D7: =SUMIFS(Eventos!$J:$J,Eventos!$I:$I,$B7,Eventos!$B:$B,D$5,Eventos!$D:$D,$C$2) -> 0 | E7: =SUMIFS(Eventos!$J:$J,Eventos!$I:$I,$B7,Eventos!$B:$B,E$5,Eventos!$D:$D,$C$2) -> 0 | F7: =SUMIFS(Eventos!$J:$J,Eventos!$I:$I,$B7,Eventos!$B:$B,F$5,Eventos!$D:$D,$C$2) -> 0 | G7: =SUMIFS(Eventos!$J:$J,Eventos!$I:$I,$B7,Eventos!$B:$B,G$5,Eventos!$D:$D,$C$2) -> 0 | H7: =SUMIFS(Eventos!$J:$J,Eventos!$I:$I,$B7,Eventos!$B:$B,H$5,Eventos!$D:$D,$C$2) -> 0 | I7: =SUMIFS(Eventos!$J:$J,Eventos!$I:$I,$B7,Eventos!$B:$B,I$5,Eventos!$D:$D,$C$2) -> 0 | J7: =SUM(C7:I7) -> 0 | M7: =SUMIFS(Eventos!$G:$G,Eventos!$F:$F,$L7,Eventos!$D:$D,$C$2,Eventos!$B:$B,PANES_SEMANALES[[#ALL],[LUNES]]) -> 0 | N7: =SUMIFS(Eventos!$G:$G,Eventos!$F:$F,$L7,Eventos!$D:$D,$C$2,Eventos!$B:$B,PANES_SEMANALES[[#ALL],[MARTES]]) -> 0 | O7: =SUMIFS(Eventos!$G:$G,Eventos!$F:$F,$L7,Eventos!$D:$D,$C$2,Eventos!$B:$B,PANES_SEMANALES[[#ALL],[MIÉRCOLES]]) -> 0 | P7: =SUMIFS(Eventos!$G:$G,Eventos!$F:$F,$L7,Eventos!$D:$D,$C$2,Eventos!$B:$B,PANES_SEMANALES[[#ALL],[JUEVES]]) -> 0 | Q7: =IF(P7<>"",SUMIFS(Eventos!$G:$G,Eventos!$B:$B,Q$2,Eventos!$D:$D,$C$2,Eventos!$F:$F,$L7),"") -> 0 | R7: =SUMIFS(Eventos!$G:$G,Eventos!$F:$F,$L7,Eventos!$D:$D,$C$2,Eventos!$B:$B,PANES_SEMANALES[[#ALL],[SÁBADO]]) -> 0 | S7: =SUMIFS(Eventos!$G:$G,Eventos!$F:$F,$L7,Eventos!$D:$D,$C$2,Eventos!$B:$B,PANES_SEMANALES[[#ALL],[DOMINGO]]) -> 0 | T7: =SUM(M7:S7) -> 0
C8: =SUMIFS(Eventos!$J:$J,Eventos!$I:$I,$B8,Eventos!$B:$B,C$5,Eventos!$D:$D,$C$2) -> 0 | D8: =SUMIFS(Eventos!$J:$J,Eventos!$I:$I,$B8,Eventos!$B:$B,D$5,Eventos!$D:$D,$C$2) -> 0 | E8: =SUMIFS(Eventos!$J:$J,Eventos!$I:$I,$B8,Eventos!$B:$B,E$5,Eventos!$D:$D,$C$2) -> 0 | F8: =SUMIFS(Eventos!$J:$J,Eventos!$I:$I,$B8,Eventos!$B:$B,F$5,Eventos!$D:$D,$C$2) -> 0 | G8: =SUMIFS(Eventos!$J:$J,Eventos!$I:$I,$B8,Eventos!$B:$B,G$5,Eventos!$D:$D,$C$2) -> 0 | H8: =SUMIFS(Eventos!$J:$J,Eventos!$I:$I,$B8,Eventos!$B:$B,H$5,Eventos!$D:$D,$C$2) -> 0 | I8: =SUMIFS(Eventos!$J:$J,Eventos!$I:$I,$B8,Eventos!$B:$B,I$5,Eventos!$D:$D,$C$2) -> 0 | J8: =SUM(C8:I8) -> 0 | M8: =SUMIFS(Eventos!$G:$G,Eventos!$F:$F,$L8,Eventos!$D:$D,$C$2,Eventos!$B:$B,PANES_SEMANALES[[#ALL],[LUNES]]) -> 0 | N8: =SUMIFS(Eventos!$G:$G,Eventos!$F:$F,$L8,Eventos!$D:$D,$C$2,Eventos!$B:$B,PANES_SEMANALES[[#ALL],[MARTES]]) -> 0 | O8: =SUMIFS(Eventos!$G:$G,Eventos!$F:$F,$L8,Eventos!$D:$D,$C$2,Eventos!$B:$B,PANES_SEMANALES[[#ALL],[MIÉRCOLES]]) -> 0 | P8: =SUMIFS(Eventos!$G:$G,Eventos!$F:$F,$L8,Eventos!$D:$D,$C$2,Eventos!$B:$B,PANES_SEMANALES[[#ALL],[JUEVES]]) -> 0 | Q8: =IF(P8<>"",SUMIFS(Eventos!$G:$G,Eventos!$B:$B,Q$2,Eventos!$D:$D,$C$2,Eventos!$F:$F,$L8),"") -> 0 | R8: =SUMIFS(Eventos!$G:$G,Eventos!$F:$F,$L8,Eventos!$D:$D,$C$2,Eventos!$B:$B,PANES_SEMANALES[[#ALL],[SÁBADO]]) -> 0 | S8: =SUMIFS(Eventos!$G:$G,Eventos!$F:$F,$L8,Eventos!$D:$D,$C$2,Eventos!$B:$B,PANES_SEMANALES[[#ALL],[DOMINGO]]) -> 0 | T8: =SUM(M8:S8) -> 0
C9: =SUMIFS(Eventos!$J:$J,Eventos!$I:$I,$B9,Eventos!$B:$B,C$5,Eventos!$D:$D,$C$2) -> 0 | D9: =SUMIFS(Eventos!$J:$J,Eventos!$I:$I,$B9,Eventos!$B:$B,D$5,Eventos!$D:$D,$C$2) -> 0 | E9: =SUMIFS(Eventos!$J:$J,Eventos!$I:$I,$B9,Eventos!$B:$B,E$5,Eventos!$D:$D,$C$2) -> 0 | F9: =SUMIFS(Eventos!$J:$J,Eventos!$I:$I,$B9,Eventos!$B:$B,F$5,Eventos!$D:$D,$C$2) -> 0 | G9: =SUMIFS(Eventos!$J:$J,Eventos!$I:$I,$B9,Eventos!$B:$B,G$5,Eventos!$D:$D,$C$2) -> 0 | H9: =SUMIFS(Eventos!$J:$J,Eventos!$I:$I,$B9,Eventos!$B:$B,H$5,Eventos!$D:$D,$C$2) -> 0 | I9: =SUMIFS(Eventos!$J:$J,Eventos!$I:$I,$B9,Eventos!$B:$B,I$5,Eventos!$D:$D,$C$2) -> 0 | J9: =SUM(C9:I9) -> 0 | M9: =SUMIFS(Eventos!$G:$G,Eventos!$F:$F,$L9,Eventos!$D:$D,$C$2,Eventos!$B:$B,PANES_SEMANALES[[#ALL],[LUNES]]) -> 0 | N9: =SUMIFS(Eventos!$G:$G,Eventos!$F:$F,$L9,Eventos!$D:$D,$C$2,Eventos!$B:$B,PANES_SEMANALES[[#ALL],[MARTES]]) -> 0 | O9: =SUMIFS(Eventos!$G:$G,Eventos!$F:$F,$L9,Eventos!$D:$D,$C$2,Eventos!$B:$B,PANES_SEMANALES[[#ALL],[MIÉRCOLES]]) -> 0 | P9: =SUMIFS(Eventos!$G:$G,Eventos!$F:$F,$L9,Eventos!$D:$D,$C$2,Eventos!$B:$B,PANES_SEMANALES[[#ALL],[JUEVES]]) -> 0 | Q9: =IF(P9<>"",SUMIFS(Eventos!$G:$G,Eventos!$B:$B,Q$2,Eventos!$D:$D,$C$2,Eventos!$F:$F,$L9),"") -> 0 | R9: =SUMIFS(Eventos!$G:$G,Eventos!$F:$F,$L9,Eventos!$D:$D,$C$2,Eventos!$B:$B,PANES_SEMANALES[[#ALL],[SÁBADO]]) -> 0 | S9: =SUMIFS(Eventos!$G:$G,Eventos!$F:$F,$L9,Eventos!$D:$D,$C$2,Eventos!$B:$B,PANES_SEMANALES[[#ALL],[DOMINGO]]) -> 0 | T9: =SUM(M9:S9) -> 0
C10: =SUMIFS(Eventos!$J:$J,Eventos!$I:$I,$B10,Eventos!$B:$B,C$5,Eventos!$D:$D,$C$2) -> 0 | D10: =SUMIFS(Eventos!$J:$J,Eventos!$I:$I,$B10,Eventos!$B:$B,D$5,Eventos!$D:$D,$C$2) -> 0 | E10: =SUMIFS(Eventos!$J:$J,Eventos!$I:$I,$B10,Eventos!$B:$B,E$5,Eventos!$D:$D,$C$2) -> 0 | F10: =SUMIFS(Eventos!$J:$J,Eventos!$I:$I,$B10,Eventos!$B:$B,F$5,Eventos!$D:$D,$C$2) -> 0 | G10: =SUMIFS(Eventos!$J:$J,Eventos!$I:$I,$B10,Eventos!$B:$B,G$5,Eventos!$D:$D,$C$2) -> 0 | H10: =SUMIFS(Eventos!$J:$J,Eventos!$I:$I,$B10,Eventos!$B:$B,H$5,Eventos!$D:$D,$C$2) -> 0 | I10: =SUMIFS(Eventos!$J:$J,Eventos!$I:$I,$B10,Eventos!$B:$B,I$5,Eventos!$D:$D,$C$2) -> 0 | J10: =SUM(C10:I10) -> 0 | M10: =SUMIFS(Eventos!$G:$G,Eventos!$F:$F,$L10,Eventos!$D:$D,$C$2,Eventos!$B:$B,PANES_SEMANALES[[#ALL],[LUNES]]) -> 0 | N10: =SUMIFS(Eventos!$G:$G,Eventos!$F:$F,$L10,Eventos!$D:$D,$C$2,Eventos!$B:$B,PANES_SEMANALES[[#ALL],[MARTES]]) -> 0 | O10: =SUMIFS(Eventos!$G:$G,Eventos!$F:$F,$L10,Eventos!$D:$D,$C$2,Eventos!$B:$B,PANES_SEMANALES[[#ALL],[MIÉRCOLES]]) -> 0 | P10: =SUMIFS(Eventos!$G:$G,Eventos!$F:$F,$L10,Eventos!$D:$D,$C$2,Eventos!$B:$B,PANES_SEMANALES[[#ALL],[JUEVES]]) -> 0 | Q10: =IF(P10<>"",SUMIFS(Eventos!$G:$G,Eventos!$B:$B,Q$2,Eventos!$D:$D,$C$2,Eventos!$F:$F,$L10),"") -> 0 | R10: =SUMIFS(Eventos!$G:$G,Eventos!$F:$F,$L10,Eventos!$D:$D,$C$2,Eventos!$B:$B,PANES_SEMANALES[[#ALL],[SÁBADO]]) -> 0 | S10: =SUMIFS(Eventos!$G:$G,Eventos!$F:$F,$L10,Eventos!$D:$D,$C$2,Eventos!$B:$B,PANES_SEMANALES[[#ALL],[DOMINGO]]) -> 0 | T10: =SUM(M10:S10) -> 0
C11: =SUMIFS(Eventos!$J:$J,Eventos!$I:$I,$B11,Eventos!$B:$B,C$5,Eventos!$D:$D,$C$2) -> 0 | D11: =SUMIFS(Eventos!$J:$J,Eventos!$I:$I,$B11,Eventos!$B:$B,D$5,Eventos!$D:$D,$C$2) -> 0 | E11: =SUMIFS(Eventos!$J:$J,Eventos!$I:$I,$B11,Eventos!$B:$B,E$5,Eventos!$D:$D,$C$2) -> 0 | F11: =SUMIFS(Eventos!$J:$J,Eventos!$I:$I,$B11,Eventos!$B:$B,F$5,Eventos!$D:$D,$C$2) -> 0 | G11: =SUMIFS(Eventos!$J:$J,Eventos!$I:$I,$B11,Eventos!$B:$B,G$5,Eventos!$D:$D,$C$2) -> 0 | H11: =SUMIFS(Eventos!$J:$J,Eventos!$I:$I,$B11,Eventos!$B:$B,H$5,Eventos!$D:$D,$C$2) -> 0 | I11: =SUMIFS(Eventos!$J:$J,Eventos!$I:$I,$B11,Eventos!$B:$B,I$5,Eventos!$D:$D,$C$2) -> 0 | J11: =SUM(C11:I11) -> 0 | M11: =SUMIFS(Eventos!$G:$G,Eventos!$F:$F,$L11,Eventos!$D:$D,$C$2,Eventos!$B:$B,PANES_SEMANALES[[#ALL],[LUNES]]) -> 0 | N11: =SUMIFS(Eventos!$G:$G,Eventos!$F:$F,$L11,Eventos!$D:$D,$C$2,Eventos!$B:$B,PANES_SEMANALES[[#ALL],[MARTES]]) -> 0 | O11: =SUMIFS(Eventos!$G:$G,Eventos!$F:$F,$L11,Eventos!$D:$D,$C$2,Eventos!$B:$B,PANES_SEMANALES[[#ALL],[MIÉRCOLES]]) -> 0 | P11: =SUMIFS(Eventos!$G:$G,Eventos!$F:$F,$L11,Eventos!$D:$D,$C$2,Eventos!$B:$B,PANES_SEMANALES[[#ALL],[JUEVES]]) -> 0 | Q11: =IF(P11<>"",SUMIFS(Eventos!$G:$G,Eventos!$B:$B,Q$2,Eventos!$D:$D,$C$2,Eventos!$F:$F,$L11),"") -> 0 | R11: =SUMIFS(Eventos!$G:$G,Eventos!$F:$F,$L11,Eventos!$D:$D,$C$2,Eventos!$B:$B,PANES_SEMANALES[[#ALL],[SÁBADO]]) -> 0 | S11: =SUMIFS(Eventos!$G:$G,Eventos!$F:$F,$L11,Eventos!$D:$D,$C$2,Eventos!$B:$B,PANES_SEMANALES[[#ALL],[DOMINGO]]) -> 0 | T11: =SUM(M11:S11) -> 0
C12: =SUMIFS(Eventos!$J:$J,Eventos!$I:$I,$B12,Eventos!$B:$B,C$5,Eventos!$D:$D,$C$2) -> 0 | D12: =SUMIFS(Eventos!$J:$J,Eventos!$I:$I,$B12,Eventos!$B:$B,D$5,Eventos!$D:$D,$C$2) -> 0 | E12: =SUMIFS(Eventos!$J:$J,Eventos!$I:$I,$B12,Eventos!$B:$B,E$5,Eventos!$D:$D,$C$2) -> 0 | F12: =SUMIFS(Eventos!$J:$J,Eventos!$I:$I,$B12,Eventos!$B:$B,F$5,Eventos!$D:$D,$C$2) -> 0 | G12: =SUMIFS(Eventos!$J:$J,Eventos!$I:$I,$B12,Eventos!$B:$B,G$5,Eventos!$D:$D,$C$2) -> 0 | H12: =SUMIFS(Eventos!$J:$J,Eventos!$I:$I,$B12,Eventos!$B:$B,H$5,Eventos!$D:$D,$C$2) -> 0 | I12: =SUMIFS(Eventos!$J:$J,Eventos!$I:$I,$B12,Eventos!$B:$B,I$5,Eventos!$D:$D,$C$2) -> 0 | J12: =SUM(C12:I12) -> 0 | M12: =SUMIFS(Eventos!$G:$G,Eventos!$F:$F,$L12,Eventos!$D:$D,$C$2,Eventos!$B:$B,PANES_SEMANALES[[#ALL],[LUNES]]) -> 0 | N12: =SUMIFS(Eventos!$G:$G,Eventos!$F:$F,$L12,Eventos!$D:$D,$C$2,Eventos!$B:$B,PANES_SEMANALES[[#ALL],[MARTES]]) -> 0 | O12: =SUMIFS(Eventos!$G:$G,Eventos!$F:$F,$L12,Eventos!$D:$D,$C$2,Eventos!$B:$B,PANES_SEMANALES[[#ALL],[MIÉRCOLES]]) -> 0 | P12: =SUMIFS(Eventos!$G:$G,Eventos!$F:$F,$L12,Eventos!$D:$D,$C$2,Eventos!$B:$B,PANES_SEMANALES[[#ALL],[JUEVES]]) -> 0 | Q12: =IF(P12<>"",SUMIFS(Eventos!$G:$G,Eventos!$B:$B,Q$2,Eventos!$D:$D,$C$2,Eventos!$F:$F,$L12),"") -> 0 | R12: =SUMIFS(Eventos!$G:$G,Eventos!$F:$F,$L12,Eventos!$D:$D,$C$2,Eventos!$B:$B,PANES_SEMANALES[[#ALL],[SÁBADO]]) -> 0 | S12: =SUMIFS(Eventos!$G:$G,Eventos!$F:$F,$L12,Eventos!$D:$D,$C$2,Eventos!$B:$B,PANES_SEMANALES[[#ALL],[DOMINGO]]) -> 0 | T12: =SUM(M12:S12) -> 0
C13: =SUMIFS(Eventos!$J:$J,Eventos!$I:$I,$B13,Eventos!$B:$B,C$5,Eventos!$D:$D,$C$2) -> 0 | D13: =SUMIFS(Eventos!$J:$J,Eventos!$I:$I,$B13,Eventos!$B:$B,D$5,Eventos!$D:$D,$C$2) -> 0 | E13: =SUMIFS(Eventos!$J:$J,Eventos!$I:$I,$B13,Eventos!$B:$B,E$5,Eventos!$D:$D,$C$2) -> 0 | F13: =SUMIFS(Eventos!$J:$J,Eventos!$I:$I,$B13,Eventos!$B:$B,F$5,Eventos!$D:$D,$C$2) -> 0 | G13: =SUMIFS(Eventos!$J:$J,Eventos!$I:$I,$B13,Eventos!$B:$B,G$5,Eventos!$D:$D,$C$2) -> 0 | H13: =SUMIFS(Eventos!$J:$J,Eventos!$I:$I,$B13,Eventos!$B:$B,H$5,Eventos!$D:$D,$C$2) -> 0 | I13: =SUMIFS(Eventos!$J:$J,Eventos!$I:$I,$B13,Eventos!$B:$B,I$5,Eventos!$D:$D,$C$2) -> 0 | J13: =SUM(C13:I13) -> 0 | M13: =SUMIFS(Eventos!$G:$G,Eventos!$F:$F,$L13,Eventos!$D:$D,$C$2,Eventos!$B:$B,PANES_SEMANALES[[#ALL],[LUNES]]) -> 0 | N13: =SUMIFS(Eventos!$G:$G,Eventos!$F:$F,$L13,Eventos!$D:$D,$C$2,Eventos!$B:$B,PANES_SEMANALES[[#ALL],[MARTES]]) -> 0 | O13: =SUMIFS(Eventos!$G:$G,Eventos!$F:$F,$L13,Eventos!$D:$D,$C$2,Eventos!$B:$B,PANES_SEMANALES[[#ALL],[MIÉRCOLES]]) -> 0 | P13: =SUMIFS(Eventos!$G:$G,Eventos!$F:$F,$L13,Eventos!$D:$D,$C$2,Eventos!$B:$B,PANES_SEMANALES[[#ALL],[JUEVES]]) -> 0 | Q13: =IF(P13<>"",SUMIFS(Eventos!$G:$G,Eventos!$B:$B,Q$2,Eventos!$D:$D,$C$2,Eventos!$F:$F,$L13),"") -> 0 | R13: =SUMIFS(Eventos!$G:$G,Eventos!$F:$F,$L13,Eventos!$D:$D,$C$2,Eventos!$B:$B,PANES_SEMANALES[[#ALL],[SÁBADO]]) -> 0 | S13: =SUMIFS(Eventos!$G:$G,Eventos!$F:$F,$L13,Eventos!$D:$D,$C$2,Eventos!$B:$B,PANES_SEMANALES[[#ALL],[DOMINGO]]) -> 0 | T13: =SUM(M13:S13) -> 0
C14: =SUMIFS(Eventos!$J:$J,Eventos!$I:$I,$B14,Eventos!$B:$B,C$5,Eventos!$D:$D,$C$2) -> 0 | D14: =SUMIFS(Eventos!$J:$J,Eventos!$I:$I,$B14,Eventos!$B:$B,D$5,Eventos!$D:$D,$C$2) -> 0 | E14: =SUMIFS(Eventos!$J:$J,Eventos!$I:$I,$B14,Eventos!$B:$B,E$5,Eventos!$D:$D,$C$2) -> 0 | F14: =SUMIFS(Eventos!$J:$J,Eventos!$I:$I,$B14,Eventos!$B:$B,F$5,Eventos!$D:$D,$C$2) -> 0 | G14: =SUMIFS(Eventos!$J:$J,Eventos!$I:$I,$B14,Eventos!$B:$B,G$5,Eventos!$D:$D,$C$2) -> 0 | H14: =SUMIFS(Eventos!$J:$J,Eventos!$I:$I,$B14,Eventos!$B:$B,H$5,Eventos!$D:$D,$C$2) -> 0 | I14: =SUMIFS(Eventos!$J:$J,Eventos!$I:$I,$B14,Eventos!$B:$B,I$5,Eventos!$D:$D,$C$2) -> 0 | J14: =SUM(C14:I14) -> 0 | M14: =SUMIFS(Eventos!$G:$G,Eventos!$F:$F,$L14,Eventos!$D:$D,$C$2,Eventos!$B:$B,PANES_SEMANALES[[#ALL],[LUNES]]) -> 0 | N14: =SUMIFS(Eventos!$G:$G,Eventos!$F:$F,$L14,Eventos!$D:$D,$C$2,Eventos!$B:$B,PANES_SEMANALES[[#ALL],[MARTES]]) -> 0 | O14: =SUMIFS(Eventos!$G:$G,Eventos!$F:$F,$L14,Eventos!$D:$D,$C$2,Eventos!$B:$B,PANES_SEMANALES[[#ALL],[MIÉRCOLES]]) -> 0 | P14: =SUMIFS(Eventos!$G:$G,Eventos!$F:$F,$L14,Eventos!$D:$D,$C$2,Eventos!$B:$B,PANES_SEMANALES[[#ALL],[JUEVES]]) -> 0 | Q14: =IF(P14<>"",SUMIFS(Eventos!$G:$G,Eventos!$B:$B,Q$2,Eventos!$D:$D,$C$2,Eventos!$F:$F,$L14),"") -> 0 | R14: =SUMIFS(Eventos!$G:$G,Eventos!$F:$F,$L14,Eventos!$D:$D,$C$2,Eventos!$B:$B,PANES_SEMANALES[[#ALL],[SÁBADO]]) -> 0 | S14: =SUMIFS(Eventos!$G:$G,Eventos!$F:$F,$L14,Eventos!$D:$D,$C$2,Eventos!$B:$B,PANES_SEMANALES[[#ALL],[DOMINGO]]) -> 0 | T14: =SUM(M14:S14) -> 0
C15: =SUMIFS(Eventos!$J:$J,Eventos!$I:$I,$B15,Eventos!$B:$B,C$5,Eventos!$D:$D,$C$2) -> 0 | D15: =SUMIFS(Eventos!$J:$J,Eventos!$I:$I,$B15,Eventos!$B:$B,D$5,Eventos!$D:$D,$C$2) -> 0 | E15: =SUMIFS(Eventos!$J:$J,Eventos!$I:$I,$B15,Eventos!$B:$B,E$5,Eventos!$D:$D,$C$2) -> 0 | F15: =SUMIFS(Eventos!$J:$J,Eventos!$I:$I,$B15,Eventos!$B:$B,F$5,Eventos!$D:$D,$C$2) -> 0 | G15: =SUMIFS(Eventos!$J:$J,Eventos!$I:$I,$B15,Eventos!$B:$B,G$5,Eventos!$D:$D,$C$2) -> 0 | H15: =SUMIFS(Eventos!$J:$J,Eventos!$I:$I,$B15,Eventos!$B:$B,H$5,Eventos!$D:$D,$C$2) -> 0 | I15: =SUMIFS(Eventos!$J:$J,Eventos!$I:$I,$B15,Eventos!$B:$B,I$5,Eventos!$D:$D,$C$2) -> 0 | J15: =SUM(C15:I15) -> 0 | M15: =SUMIFS(Eventos!$G:$G,Eventos!$F:$F,$L15,Eventos!$D:$D,$C$2,Eventos!$B:$B,PANES_SEMANALES[[#ALL],[LUNES]]) -> 0 | N15: =SUMIFS(Eventos!$G:$G,Eventos!$F:$F,$L15,Eventos!$D:$D,$C$2,Eventos!$B:$B,PANES_SEMANALES[[#ALL],[MARTES]]) -> 0 | O15: =SUMIFS(Eventos!$G:$G,Eventos!$F:$F,$L15,Eventos!$D:$D,$C$2,Eventos!$B:$B,PANES_SEMANALES[[#ALL],[MIÉRCOLES]]) -> 0 | P15: =SUMIFS(Eventos!$G:$G,Eventos!$F:$F,$L15,Eventos!$D:$D,$C$2,Eventos!$B:$B,PANES_SEMANALES[[#ALL],[JUEVES]]) -> 0 | Q15: =IF(P15<>"",SUMIFS(Eventos!$G:$G,Eventos!$B:$B,Q$2,Eventos!$D:$D,$C$2,Eventos!$F:$F,$L15),"") -> 0 | R15: =SUMIFS(Eventos!$G:$G,Eventos!$F:$F,$L15,Eventos!$D:$D,$C$2,Eventos!$B:$B,PANES_SEMANALES[[#ALL],[SÁBADO]]) -> 0 | S15: =SUMIFS(Eventos!$G:$G,Eventos!$F:$F,$L15,Eventos!$D:$D,$C$2,Eventos!$B:$B,PANES_SEMANALES[[#ALL],[DOMINGO]]) -> 0 | T15: =SUM(M15:S15) -> 0
C16: =SUMIFS(Eventos!$J:$J,Eventos!$I:$I,$B16,Eventos!$B:$B,C$5,Eventos!$D:$D,$C$2) -> 0 | D16: =SUMIFS(Eventos!$J:$J,Eventos!$I:$I,$B16,Eventos!$B:$B,D$5,Eventos!$D:$D,$C$2) -> 0 | E16: =SUMIFS(Eventos!$J:$J,Eventos!$I:$I,$B16,Eventos!$B:$B,E$5,Eventos!$D:$D,$C$2) -> 0 | F16: =SUMIFS(Eventos!$J:$J,Eventos!$I:$I,$B16,Eventos!$B:$B,F$5,Eventos!$D:$D,$C$2) -> 0 | G16: =SUMIFS(Eventos!$J:$J,Eventos!$I:$I,$B16,Eventos!$B:$B,G$5,Eventos!$D:$D,$C$2) -> 0 | H16: =SUMIFS(Eventos!$J:$J,Eventos!$I:$I,$B16,Eventos!$B:$B,H$5,Eventos!$D:$D,$C$2) -> 0 | I16: =SUMIFS(Eventos!$J:$J,Eventos!$I:$I,$B16,Eventos!$B:$B,I$5,Eventos!$D:$D,$C$2) -> 0 | J16: =SUM(C16:I16) -> 0 | M16: =SUMIFS(Eventos!$G:$G,Eventos!$F:$F,$L16,Eventos!$D:$D,$C$2,Eventos!$B:$B,PANES_SEMANALES[[#ALL],[LUNES]]) -> 0 | N16: =SUMIFS(Eventos!$G:$G,Eventos!$F:$F,$L16,Eventos!$D:$D,$C$2,Eventos!$B:$B,PANES_SEMANALES[[#ALL],[MARTES]]) -> 0 | O16: =SUMIFS(Eventos!$G:$G,Eventos!$F:$F,$L16,Eventos!$D:$D,$C$2,Eventos!$B:$B,PANES_SEMANALES[[#ALL],[MIÉRCOLES]]) -> 0 | P16: =SUMIFS(Eventos!$G:$G,Eventos!$F:$F,$L16,Eventos!$D:$D,$C$2,Eventos!$B:$B,PANES_SEMANALES[[#ALL],[JUEVES]]) -> 0 | Q16: =IF(P16<>"",SUMIFS(Eventos!$G:$G,Eventos!$B:$B,Q$2,Eventos!$D:$D,$C$2,Eventos!$F:$F,$L16),"") -> 0 | R16: =SUMIFS(Eventos!$G:$G,Eventos!$F:$F,$L16,Eventos!$D:$D,$C$2,Eventos!$B:$B,PANES_SEMANALES[[#ALL],[SÁBADO]]) -> 0 | S16: =SUMIFS(Eventos!$G:$G,Eventos!$F:$F,$L16,Eventos!$D:$D,$C$2,Eventos!$B:$B,PANES_SEMANALES[[#ALL],[DOMINGO]]) -> 0 | T16: =SUM(M16:S16) -> 0
C17: =SUMIFS(Eventos!$J:$J,Eventos!$I:$I,$B17,Eventos!$B:$B,C$5,Eventos!$D:$D,$C$2) -> 0 | D17: =SUMIFS(Eventos!$J:$J,Eventos!$I:$I,$B17,Eventos!$B:$B,D$5,Eventos!$D:$D,$C$2) -> 0 | E17: =SUMIFS(Eventos!$J:$J,Eventos!$I:$I,$B17,Eventos!$B:$B,E$5,Eventos!$D:$D,$C$2) -> 0 | F17: =SUMIFS(Eventos!$J:$J,Eventos!$I:$I,$B17,Eventos!$B:$B,F$5,Eventos!$D:$D,$C$2) -> 0 | G17: =SUMIFS(Eventos!$J:$J,Eventos!$I:$I,$B17,Eventos!$B:$B,G$5,Eventos!$D:$D,$C$2) -> 0 | H17: =SUMIFS(Eventos!$J:$J,Eventos!$I:$I,$B17,Eventos!$B:$B,H$5,Eventos!$D:$D,$C$2) -> 0 | I17: =SUMIFS(Eventos!$J:$J,Eventos!$I:$I,$B17,Eventos!$B:$B,I$5,Eventos!$D:$D,$C$2) -> 0 | J17: =SUM(C17:I17) -> 0 | M17: =SUMIFS(Eventos!$G:$G,Eventos!$F:$F,$L17,Eventos!$D:$D,$C$2,Eventos!$B:$B,PANES_SEMANALES[[#ALL],[LUNES]]) -> 0 | N17: =SUMIFS(Eventos!$G:$G,Eventos!$F:$F,$L17,Eventos!$D:$D,$C$2,Eventos!$B:$B,PANES_SEMANALES[[#ALL],[MARTES]]) -> 0 | O17: =SUMIFS(Eventos!$G:$G,Eventos!$F:$F,$L17,Eventos!$D:$D,$C$2,Eventos!$B:$B,PANES_SEMANALES[[#ALL],[MIÉRCOLES]]) -> 0 | P17: =SUMIFS(Eventos!$G:$G,Eventos!$F:$F,$L17,Eventos!$D:$D,$C$2,Eventos!$B:$B,PANES_SEMANALES[[#ALL],[JUEVES]]) -> 0 | Q17: =IF(P17<>"",SUMIFS(Eventos!$G:$G,Eventos!$B:$B,Q$2,Eventos!$D:$D,$C$2,Eventos!$F:$F,$L17),"") -> 0 | R17: =SUMIFS(Eventos!$G:$G,Eventos!$F:$F,$L17,Eventos!$D:$D,$C$2,Eventos!$B:$B,PANES_SEMANALES[[#ALL],[SÁBADO]]) -> 0 | S17: =SUMIFS(Eventos!$G:$G,Eventos!$F:$F,$L17,Eventos!$D:$D,$C$2,Eventos!$B:$B,PANES_SEMANALES[[#ALL],[DOMINGO]]) -> 0 | T17: =SUM(M17:S17) -> 0
C18: =SUMIFS(Eventos!$J:$J,Eventos!$I:$I,$B18,Eventos!$B:$B,C$5,Eventos!$D:$D,$C$2) -> 0 | D18: =SUMIFS(Eventos!$J:$J,Eventos!$I:$I,$B18,Eventos!$B:$B,D$5,Eventos!$D:$D,$C$2) -> 0 | E18: =SUMIFS(Eventos!$J:$J,Eventos!$I:$I,$B18,Eventos!$B:$B,E$5,Eventos!$D:$D,$C$2) -> 0 | F18: =SUMIFS(Eventos!$J:$J,Eventos!$I:$I,$B18,Eventos!$B:$B,F$5,Eventos!$D:$D,$C$2) -> 0 | G18: =SUMIFS(Eventos!$J:$J,Eventos!$I:$I,$B18,Eventos!$B:$B,G$5,Eventos!$D:$D,$C$2) -> 0 | H18: =SUMIFS(Eventos!$J:$J,Eventos!$I:$I,$B18,Eventos!$B:$B,H$5,Eventos!$D:$D,$C$2) -> 0 | I18: =SUMIFS(Eventos!$J:$J,Eventos!$I:$I,$B18,Eventos!$B:$B,I$5,Eventos!$D:$D,$C$2) -> 0 | J18: =SUM(C18:I18) -> 0 | M18: =SUMIFS(Eventos!$G:$G,Eventos!$F:$F,$L18,Eventos!$D:$D,$C$2,Eventos!$B:$B,PANES_SEMANALES[[#ALL],[LUNES]]) -> 0 | N18: =SUMIFS(Eventos!$G:$G,Eventos!$F:$F,$L18,Eventos!$D:$D,$C$2,Eventos!$B:$B,PANES_SEMANALES[[#ALL],[MARTES]]) -> 0 | O18: =SUMIFS(Eventos!$G:$G,Eventos!$F:$F,$L18,Eventos!$D:$D,$C$2,Eventos!$B:$B,PANES_SEMANALES[[#ALL],[MIÉRCOLES]]) -> 0 | P18: =SUMIFS(Eventos!$G:$G,Eventos!$F:$F,$L18,Eventos!$D:$D,$C$2,Eventos!$B:$B,PANES_SEMANALES[[#ALL],[JUEVES]]) -> 0 | Q18: =IF(P18<>"",SUMIFS(Eventos!$G:$G,Eventos!$B:$B,Q$2,Eventos!$D:$D,$C$2,Eventos!$F:$F,$L18),"") -> 0 | R18: =SUMIFS(Eventos!$G:$G,Eventos!$F:$F,$L18,Eventos!$D:$D,$C$2,Eventos!$B:$B,PANES_SEMANALES[[#ALL],[SÁBADO]]) -> 0 | S18: =SUMIFS(Eventos!$G:$G,Eventos!$F:$F,$L18,Eventos!$D:$D,$C$2,Eventos!$B:$B,PANES_SEMANALES[[#ALL],[DOMINGO]]) -> 0 | T18: =SUM(M18:S18) -> 0
... C35: =SUMIFS(Eventos!$J:$J,Eventos!$I:$I,$B35,Eventos!$B:$B,C$5,Eventos!$D:$D,$C$2) -> 0 | D35: =SUMIFS(Eventos!$J:$J,Eventos!$I:$I,$B35,Eventos!$B:$B,D$5,Eventos!$D:$D,$C$2) -> 0 | E35: =SUMIFS(Eventos!$J:$J,Eventos!$I:$I,$B35,Eventos!$B:$B,E$5,Eventos!$D:$D,$C$2) -> 0 | F35: =SUMIFS(Eventos!$J:$J,Eventos!$I:$I,$B35,Eventos!$B:$B,F$5,Eventos!$D:$D,$C$2) -> 0 | G35: =SUMIFS(Eventos!$J:$J,Eventos!$I:$I,$B35,Eventos!$B:$B,G$5,Eventos!$D:$D,$C$2) -> 0 | H35: =SUMIFS(Eventos!$J:$J,Eventos!$I:$I,$B35,Eventos!$B:$B,H$5,Eventos!$D:$D,$C$2) -> 0 | I35: =SUMIFS(Eventos!$J:$J,Eventos!$I:$I,$B35,Eventos!$B:$B,I$5,Eventos!$D:$D,$C$2) -> 0 | J35: =SUM(C35:I35) -> 0 | M35: =SUMIFS(Eventos!$G:$G,Eventos!$F:$F,$L35,Eventos!$D:$D,$C$2,Eventos!$B:$B,PANES_SEMANALES[[#ALL],[LUNES]]) -> 0 | N35: =SUMIFS(Eventos!$G:$G,Eventos!$F:$F,$L35,Eventos!$D:$D,$C$2,Eventos!$B:$B,PANES_SEMANALES[[#ALL],[MARTES]]) -> 0 | O35: =SUMIFS(Eventos!$G:$G,Eventos!$F:$F,$L35,Eventos!$D:$D,$C$2,Eventos!$B:$B,PANES_SEMANALES[[#ALL],[MIÉRCOLES]]) -> 0 | P35: =SUMIFS(Eventos!$G:$G,Eventos!$F:$F,$L35,Eventos!$D:$D,$C$2,Eventos!$B:$B,PANES_SEMANALES[[#ALL],[JUEVES]]) -> 0 | Q35: =IF(P35<>"",SUMIFS(Eventos!$G:$G,Eventos!$B:$B,Q$2,Eventos!$D:$D,$C$2,Eventos!$F:$F,$L35),"") -> 0 | R35: =SUMIFS(Eventos!$G:$G,Eventos!$F:$F,$L35,Eventos!$D:$D,$C$2,Eventos!$B:$B,PANES_SEMANALES[[#ALL],[SÁBADO]]) -> 0 | S35: =SUMIFS(Eventos!$G:$G,Eventos!$F:$F,$L35,Eventos!$D:$D,$C$2,Eventos!$B:$B,PANES_SEMANALES[[#ALL],[DOMINGO]]) -> 0 | T35: =SUM(M35:S35) -> 0
M36: =SUMIFS(Eventos!$G:$G,Eventos!$F:$F,$L36,Eventos!$D:$D,$C$2,Eventos!$B:$B,PANES_SEMANALES[[#ALL],[LUNES]]) -> 0 | N36: =SUMIFS(Eventos!$G:$G,Eventos!$F:$F,$L36,Eventos!$D:$D,$C$2,Eventos!$B:$B,PANES_SEMANALES[[#ALL],[MARTES]]) -> 0 | O36: =SUMIFS(Eventos!$G:$G,Eventos!$F:$F,$L36,Eventos!$D:$D,$C$2,Eventos!$B:$B,PANES_SEMANALES[[#ALL],[MIÉRCOLES]]) -> 0 | P36: =SUMIFS(Eventos!$G:$G,Eventos!$F:$F,$L36,Eventos!$D:$D,$C$2,Eventos!$B:$B,PANES_SEMANALES[[#ALL],[JUEVES]]) -> 0 | Q36: =IF(P36<>"",SUMIFS(Eventos!$G:$G,Eventos!$B:$B,Q$2,Eventos!$D:$D,$C$2,Eventos!$F:$F,$L36),"") -> 0 | R36: =SUMIFS(Eventos!$G:$G,Eventos!$F:$F,$L36,Eventos!$D:$D,$C$2,Eventos!$B:$B,PANES_SEMANALES[[#ALL],[SÁBADO]]) -> 0 | S36: =SUMIFS(Eventos!$G:$G,Eventos!$F:$F,$L36,Eventos!$D:$D,$C$2,Eventos!$B:$B,PANES_SEMANALES[[#ALL],[DOMINGO]]) -> 0 | T36: =SUM(M36:S36) -> 0
M37: =SUMIFS(Eventos!$G:$G,Eventos!$F:$F,$L37,Eventos!$D:$D,$C$2,Eventos!$B:$B,PANES_SEMANALES[[#ALL],[LUNES]]) -> 0 | N37: =SUMIFS(Eventos!$G:$G,Eventos!$F:$F,$L37,Eventos!$D:$D,$C$2,Eventos!$B:$B,PANES_SEMANALES[[#ALL],[MARTES]]) -> 0 | O37: =SUMIFS(Eventos!$G:$G,Eventos!$F:$F,$L37,Eventos!$D:$D,$C$2,Eventos!$B:$B,PANES_SEMANALES[[#ALL],[MIÉRCOLES]]) -> 0 | P37: =SUMIFS(Eventos!$G:$G,Eventos!$F:$F,$L37,Eventos!$D:$D,$C$2,Eventos!$B:$B,PANES_SEMANALES[[#ALL],[JUEVES]]) -> 0 | Q37: =IF(P37<>"",SUMIFS(Eventos!$G:$G,Eventos!$B:$B,Q$2,Eventos!$D:$D,$C$2,Eventos!$F:$F,$L37),"") -> 0 | R37: =SUMIFS(Eventos!$G:$G,Eventos!$F:$F,$L37,Eventos!$D:$D,$C$2,Eventos!$B:$B,PANES_SEMANALES[[#ALL],[SÁBADO]]) -> 0 | S37: =SUMIFS(Eventos!$G:$G,Eventos!$F:$F,$L37,Eventos!$D:$D,$C$2,Eventos!$B:$B,PANES_SEMANALES[[#ALL],[DOMINGO]]) -> 0 | T37: =SUM(M37:S37) -> 0
M38: =SUMIFS(Eventos!$G:$G,Eventos!$F:$F,$L38,Eventos!$D:$D,$C$2,Eventos!$B:$B,PANES_SEMANALES[[#ALL],[LUNES]]) -> 0 | N38: =SUMIFS(Eventos!$G:$G,Eventos!$F:$F,$L38,Eventos!$D:$D,$C$2,Eventos!$B:$B,PANES_SEMANALES[[#ALL],[MARTES]]) -> 0 | O38: =SUMIFS(Eventos!$G:$G,Eventos!$F:$F,$L38,Eventos!$D:$D,$C$2,Eventos!$B:$B,PANES_SEMANALES[[#ALL],[MIÉRCOLES]]) -> 0 | P38: =SUMIFS(Eventos!$G:$G,Eventos!$F:$F,$L38,Eventos!$D:$D,$C$2,Eventos!$B:$B,PANES_SEMANALES[[#ALL],[JUEVES]]) -> 0 | Q38: =IF(P38<>"",SUMIFS(Eventos!$G:$G,Eventos!$B:$B,Q$2,Eventos!$D:$D,$C$2,Eventos!$F:$F,$L38),"") -> 0 | R38: =SUMIFS(Eventos!$G:$G,Eventos!$F:$F,$L38,Eventos!$D:$D,$C$2,Eventos!$B:$B,PANES_SEMANALES[[#ALL],[SÁBADO]]) -> 0 | S38: =SUMIFS(Eventos!$G:$G,Eventos!$F:$F,$L38,Eventos!$D:$D,$C$2,Eventos!$B:$B,PANES_SEMANALES[[#ALL],[DOMINGO]]) -> 0 | T38: =SUM(M38:S38) -> 0
B39: RESUMEN PROTEINA SEMANAL | C39: LUNES | D39: MARTES | E39: MIÉRCOLES | F39: JUEVES | G39: VIERNES | H39: SÁBADO | I39: DOMINGO | J39: TOTAL | M39: =SUMIFS(Eventos!$G:$G,Eventos!$F:$F,$L39,Eventos!$D:$D,$C$2,Eventos!$B:$B,PANES_SEMANALES[[#ALL],[LUNES]]) -> 0 | N39: =SUMIFS(Eventos!$G:$G,Eventos!$F:$F,$L39,Eventos!$D:$D,$C$2,Eventos!$B:$B,PANES_SEMANALES[[#ALL],[MARTES]]) -> 0 | O39: =SUMIFS(Eventos!$G:$G,Eventos!$F:$F,$L39,Eventos!$D:$D,$C$2,Eventos!$B:$B,PANES_SEMANALES[[#ALL],[MIÉRCOLES]]) -> 0 | P39: =SUMIFS(Eventos!$G:$G,Eventos!$F:$F,$L39,Eventos!$D:$D,$C$2,Eventos!$B:$B,PANES_SEMANALES[[#ALL],[JUEVES]]) -> 0 | Q39: =IF(P39<>"",SUMIFS(Eventos!$G:$G,Eventos!$B:$B,Q$2,Eventos!$D:$D,$C$2,Eventos!$F:$F,$L39),"") -> 0 | R39: =SUMIFS(Eventos!$G:$G,Eventos!$F:$F,$L39,Eventos!$D:$D,$C$2,Eventos!$B:$B,PANES_SEMANALES[[#ALL],[SÁBADO]]) -> 0 | S39: =SUMIFS(Eventos!$G:$G,Eventos!$F:$F,$L39,Eventos!$D:$D,$C$2,Eventos!$B:$B,PANES_SEMANALES[[#ALL],[DOMINGO]]) -> 0 | T39: =SUM(M39:S39) -> 0
A40: {=SEQUENCE(COUNTA(B40:B53),1)} -> 1 | B40: =IFERROR(__xludf.DUMMYFUNCTION("SORT(UNIQUE(FILTER(Eventos!K:K,Eventos!D:D=C2)),1,TRUE)"),"#N/A") -> #N/A | C40: =SUMIFS(Eventos!$L:$L,Eventos!$B:$B,C$39,Eventos!$K:$K,$B40,Eventos!$D:$D,$C$2) -> 0 | D40: =SUMIFS(Eventos!$L:$L,Eventos!$B:$B,D$39,Eventos!$K:$K,$B40,Eventos!$D:$D,$C$2) -> 0 | E40: =SUMIFS(Eventos!$L:$L,Eventos!$B:$B,E$39,Eventos!$K:$K,$B40,Eventos!$D:$D,$C$2) -> 0 | F40: =SUMIFS(Eventos!$L:$L,Eventos!$B:$B,F$39,Eventos!$K:$K,$B40,Eventos!$D:$D,$C$2) -> 0 | G40: =SUMIFS(Eventos!$L:$L,Eventos!$B:$B,G$39,Eventos!$K:$K,$B40,Eventos!$D:$D,$C$2) -> 0 | H40: =SUMIFS(Eventos!$L:$L,Eventos!$B:$B,H$39,Eventos!$K:$K,$B40,Eventos!$D:$D,$C$2) -> 0 | I40: =SUMIFS(Eventos!$L:$L,Eventos!$B:$B,I$39,Eventos!$K:$K,$B40,Eventos!$D:$D,$C$2) -> 0 | J40: =SUM(C40:I40) -> 0 | M40: =SUMIFS(Eventos!$G:$G,Eventos!$F:$F,$L40,Eventos!$D:$D,$C$2,Eventos!$B:$B,PANES_SEMANALES[[#ALL],[LUNES]]) -> 0 | N40: =SUMIFS(Eventos!$G:$G,Eventos!$F:$F,$L40,Eventos!$D:$D,$C$2,Eventos!$B:$B,PANES_SEMANALES[[#ALL],[MARTES]]) -> 0 | O40: =SUMIFS(Eventos!$G:$G,Eventos!$F:$F,$L40,Eventos!$D:$D,$C$2,Eventos!$B:$B,PANES_SEMANALES[[#ALL],[MIÉRCOLES]]) -> 0 | P40: =SUMIFS(Eventos!$G:$G,Eventos!$F:$F,$L40,Eventos!$D:$D,$C$2,Eventos!$B:$B,PANES_SEMANALES[[#ALL],[JUEVES]]) -> 0 | Q40: =IF(P40<>"",SUMIFS(Eventos!$G:$G,Eventos!$B:$B,Q$2,Eventos!$D:$D,$C$2,Eventos!$F:$F,$L40),"") -> 0 | R40: =SUMIFS(Eventos!$G:$G,Eventos!$F:$F,$L40,Eventos!$D:$D,$C$2,Eventos!$B:$B,PANES_SEMANALES[[#ALL],[SÁBADO]]) -> 0 | S40: =SUMIFS(Eventos!$G:$G,Eventos!$F:$F,$L40,Eventos!$D:$D,$C$2,Eventos!$B:$B,PANES_SEMANALES[[#ALL],[DOMINGO]]) -> 0 | T40: =SUM(M40:S40) -> 0
C41: =SUMIFS(Eventos!$L:$L,Eventos!$B:$B,C$39,Eventos!$K:$K,$B41,Eventos!$D:$D,$C$2) -> 0 | D41: =SUMIFS(Eventos!$L:$L,Eventos!$B:$B,D$39,Eventos!$K:$K,$B41,Eventos!$D:$D,$C$2) -> 0 | E41: =SUMIFS(Eventos!$L:$L,Eventos!$B:$B,E$39,Eventos!$K:$K,$B41,Eventos!$D:$D,$C$2) -> 0 | F41: =SUMIFS(Eventos!$L:$L,Eventos!$B:$B,F$39,Eventos!$K:$K,$B41,Eventos!$D:$D,$C$2) -> 0 | G41: =SUMIFS(Eventos!$L:$L,Eventos!$B:$B,G$39,Eventos!$K:$K,$B41,Eventos!$D:$D,$C$2) -> 0 | H41: =SUMIFS(Eventos!$L:$L,Eventos!$B:$B,H$39,Eventos!$K:$K,$B41,Eventos!$D:$D,$C$2) -> 0 | I41: =SUMIFS(Eventos!$L:$L,Eventos!$B:$B,I$39,Eventos!$K:$K,$B41,Eventos!$D:$D,$C$2) -> 0 | J41: =SUM(C41:I41) -> 0 | M41: =SUMIFS(Eventos!$G:$G,Eventos!$F:$F,$L41,Eventos!$D:$D,$C$2,Eventos!$B:$B,PANES_SEMANALES[[#ALL],[LUNES]]) -> 0 | N41: =SUMIFS(Eventos!$G:$G,Eventos!$F:$F,$L41,Eventos!$D:$D,$C$2,Eventos!$B:$B,PANES_SEMANALES[[#ALL],[MARTES]]) -> 0 | O41: =SUMIFS(Eventos!$G:$G,Eventos!$F:$F,$L41,Eventos!$D:$D,$C$2,Eventos!$B:$B,PANES_SEMANALES[[#ALL],[MIÉRCOLES]]) -> 0 | P41: =SUMIFS(Eventos!$G:$G,Eventos!$F:$F,$L41,Eventos!$D:$D,$C$2,Eventos!$B:$B,PANES_SEMANALES[[#ALL],[JUEVES]]) -> 0 | Q41: =IF(P41<>"",SUMIFS(Eventos!$G:$G,Eventos!$B:$B,Q$2,Eventos!$D:$D,$C$2,Eventos!$F:$F,$L41),"") -> 0 | R41: =SUMIFS(Eventos!$G:$G,Eventos!$F:$F,$L41,Eventos!$D:$D,$C$2,Eventos!$B:$B,PANES_SEMANALES[[#ALL],[SÁBADO]]) -> 0 | S41: =SUMIFS(Eventos!$G:$G,Eventos!$F:$F,$L41,Eventos!$D:$D,$C$2,Eventos!$B:$B,PANES_SEMANALES[[#ALL],[DOMINGO]]) -> 0 | T41: =SUM(M41:S41) -> 0
C42: =SUMIFS(Eventos!$L:$L,Eventos!$B:$B,C$39,Eventos!$K:$K,$B42,Eventos!$D:$D,$C$2) -> 0 | D42: =SUMIFS(Eventos!$L:$L,Eventos!$B:$B,D$39,Eventos!$K:$K,$B42,Eventos!$D:$D,$C$2) -> 0 | E42: =SUMIFS(Eventos!$L:$L,Eventos!$B:$B,E$39,Eventos!$K:$K,$B42,Eventos!$D:$D,$C$2) -> 0 | F42: =SUMIFS(Eventos!$L:$L,Eventos!$B:$B,F$39,Eventos!$K:$K,$B42,Eventos!$D:$D,$C$2) -> 0 | G42: =SUMIFS(Eventos!$L:$L,Eventos!$B:$B,G$39,Eventos!$K:$K,$B42,Eventos!$D:$D,$C$2) -> 0 | H42: =SUMIFS(Eventos!$L:$L,Eventos!$B:$B,H$39,Eventos!$K:$K,$B42,Eventos!$D:$D,$C$2) -> 0 | I42: =SUMIFS(Eventos!$L:$L,Eventos!$B:$B,I$39,Eventos!$K:$K,$B42,Eventos!$D:$D,$C$2) -> 0 | J42: =SUM(C42:I42) -> 0 | M42: =SUMIFS(Eventos!$G:$G,Eventos!$F:$F,$L42,Eventos!$D:$D,$C$2,Eventos!$B:$B,PANES_SEMANALES[[#ALL],[LUNES]]) -> 0 | N42: =SUMIFS(Eventos!$G:$G,Eventos!$F:$F,$L42,Eventos!$D:$D,$C$2,Eventos!$B:$B,PANES_SEMANALES[[#ALL],[MARTES]]) -> 0 | O42: =SUMIFS(Eventos!$G:$G,Eventos!$F:$F,$L42,Eventos!$D:$D,$C$2,Eventos!$B:$B,PANES_SEMANALES[[#ALL],[MIÉRCOLES]]) -> 0 | P42: =SUMIFS(Eventos!$G:$G,Eventos!$F:$F,$L42,Eventos!$D:$D,$C$2,Eventos!$B:$B,PANES_SEMANALES[[#ALL],[JUEVES]]) -> 0 | Q42: =IF(P42<>"",SUMIFS(Eventos!$G:$G,Eventos!$B:$B,Q$2,Eventos!$D:$D,$C$2,Eventos!$F:$F,$L42),"") -> 0 | R42: =SUMIFS(Eventos!$G:$G,Eventos!$F:$F,$L42,Eventos!$D:$D,$C$2,Eventos!$B:$B,PANES_SEMANALES[[#ALL],[SÁBADO]]) -> 0 | S42: =SUMIFS(Eventos!$G:$G,Eventos!$F:$F,$L42,Eventos!$D:$D,$C$2,Eventos!$B:$B,PANES_SEMANALES[[#ALL],[DOMINGO]]) -> 0 | T42: =SUM(M42:S42) -> 0
C43: =SUMIFS(Eventos!$L:$L,Eventos!$B:$B,C$39,Eventos!$K:$K,$B43,Eventos!$D:$D,$C$2) -> 0 | D43: =SUMIFS(Eventos!$L:$L,Eventos!$B:$B,D$39,Eventos!$K:$K,$B43,Eventos!$D:$D,$C$2) -> 0 | E43: =SUMIFS(Eventos!$L:$L,Eventos!$B:$B,E$39,Eventos!$K:$K,$B43,Eventos!$D:$D,$C$2) -> 0 | F43: =SUMIFS(Eventos!$L:$L,Eventos!$B:$B,F$39,Eventos!$K:$K,$B43,Eventos!$D:$D,$C$2) -> 0 | G43: =SUMIFS(Eventos!$L:$L,Eventos!$B:$B,G$39,Eventos!$K:$K,$B43,Eventos!$D:$D,$C$2) -> 0 | H43: =SUMIFS(Eventos!$L:$L,Eventos!$B:$B,H$39,Eventos!$K:$K,$B43,Eventos!$D:$D,$C$2) -> 0 | I43: =SUMIFS(Eventos!$L:$L,Eventos!$B:$B,I$39,Eventos!$K:$K,$B43,Eventos!$D:$D,$C$2) -> 0 | J43: =SUM(C43:I43) -> 0 | M43: =SUMIFS(Eventos!$G:$G,Eventos!$F:$F,$L43,Eventos!$D:$D,$C$2,Eventos!$B:$B,PANES_SEMANALES[[#ALL],[LUNES]]) -> 0 | N43: =SUMIFS(Eventos!$G:$G,Eventos!$F:$F,$L43,Eventos!$D:$D,$C$2,Eventos!$B:$B,PANES_SEMANALES[[#ALL],[MARTES]]) -> 0 | O43: =SUMIFS(Eventos!$G:$G,Eventos!$F:$F,$L43,Eventos!$D:$D,$C$2,Eventos!$B:$B,PANES_SEMANALES[[#ALL],[MIÉRCOLES]]) -> 0 | P43: =SUMIFS(Eventos!$G:$G,Eventos!$F:$F,$L43,Eventos!$D:$D,$C$2,Eventos!$B:$B,PANES_SEMANALES[[#ALL],[JUEVES]]) -> 0 | Q43: =IF(P43<>"",SUMIFS(Eventos!$G:$G,Eventos!$B:$B,Q$2,Eventos!$D:$D,$C$2,Eventos!$F:$F,$L43),"") -> 0 | R43: =SUMIFS(Eventos!$G:$G,Eventos!$F:$F,$L43,Eventos!$D:$D,$C$2,Eventos!$B:$B,PANES_SEMANALES[[#ALL],[SÁBADO]]) -> 0 | S43: =SUMIFS(Eventos!$G:$G,Eventos!$F:$F,$L43,Eventos!$D:$D,$C$2,Eventos!$B:$B,PANES_SEMANALES[[#ALL],[DOMINGO]]) -> 0 | T43: =SUM(M43:S43) -> 0
C44: =SUMIFS(Eventos!$L:$L,Eventos!$B:$B,C$39,Eventos!$K:$K,$B44,Eventos!$D:$D,$C$2) -> 0 | D44: =SUMIFS(Eventos!$L:$L,Eventos!$B:$B,D$39,Eventos!$K:$K,$B44,Eventos!$D:$D,$C$2) -> 0 | E44: =SUMIFS(Eventos!$L:$L,Eventos!$B:$B,E$39,Eventos!$K:$K,$B44,Eventos!$D:$D,$C$2) -> 0 | F44: =SUMIFS(Eventos!$L:$L,Eventos!$B:$B,F$39,Eventos!$K:$K,$B44,Eventos!$D:$D,$C$2) -> 0 | G44: =SUMIFS(Eventos!$L:$L,Eventos!$B:$B,G$39,Eventos!$K:$K,$B44,Eventos!$D:$D,$C$2) -> 0 | H44: =SUMIFS(Eventos!$L:$L,Eventos!$B:$B,H$39,Eventos!$K:$K,$B44,Eventos!$D:$D,$C$2) -> 0 | I44: =SUMIFS(Eventos!$L:$L,Eventos!$B:$B,I$39,Eventos!$K:$K,$B44,Eventos!$D:$D,$C$2) -> 0 | J44: =SUM(C44:I44) -> 0 | M44: =SUMIFS(Eventos!$G:$G,Eventos!$F:$F,$L44,Eventos!$D:$D,$C$2,Eventos!$B:$B,PANES_SEMANALES[[#ALL],[LUNES]]) -> 0 | N44: =SUMIFS(Eventos!$G:$G,Eventos!$F:$F,$L44,Eventos!$D:$D,$C$2,Eventos!$B:$B,PANES_SEMANALES[[#ALL],[MARTES]]) -> 0 | O44: =SUMIFS(Eventos!$G:$G,Eventos!$F:$F,$L44,Eventos!$D:$D,$C$2,Eventos!$B:$B,PANES_SEMANALES[[#ALL],[MIÉRCOLES]]) -> 0 | P44: =SUMIFS(Eventos!$G:$G,Eventos!$F:$F,$L44,Eventos!$D:$D,$C$2,Eventos!$B:$B,PANES_SEMANALES[[#ALL],[JUEVES]]) -> 0 | Q44: =IF(P44<>"",SUMIFS(Eventos!$G:$G,Eventos!$B:$B,Q$2,Eventos!$D:$D,$C$2,Eventos!$F:$F,$L44),"") -> 0 | R44: =SUMIFS(Eventos!$G:$G,Eventos!$F:$F,$L44,Eventos!$D:$D,$C$2,Eventos!$B:$B,PANES_SEMANALES[[#ALL],[SÁBADO]]) -> 0 | S44: =SUMIFS(Eventos!$G:$G,Eventos!$F:$F,$L44,Eventos!$D:$D,$C$2,Eventos!$B:$B,PANES_SEMANALES[[#ALL],[DOMINGO]]) -> 0 | T44: =SUM(M44:S44) -> 0
C45: =SUMIFS(Eventos!$L:$L,Eventos!$B:$B,C$39,Eventos!$K:$K,$B45,Eventos!$D:$D,$C$2) -> 0 | D45: =SUMIFS(Eventos!$L:$L,Eventos!$B:$B,D$39,Eventos!$K:$K,$B45,Eventos!$D:$D,$C$2) -> 0 | E45: =SUMIFS(Eventos!$L:$L,Eventos!$B:$B,E$39,Eventos!$K:$K,$B45,Eventos!$D:$D,$C$2) -> 0 | F45: =SUMIFS(Eventos!$L:$L,Eventos!$B:$B,F$39,Eventos!$K:$K,$B45,Eventos!$D:$D,$C$2) -> 0 | G45: =SUMIFS(Eventos!$L:$L,Eventos!$B:$B,G$39,Eventos!$K:$K,$B45,Eventos!$D:$D,$C$2) -> 0 | H45: =SUMIFS(Eventos!$L:$L,Eventos!$B:$B,H$39,Eventos!$K:$K,$B45,Eventos!$D:$D,$C$2) -> 0 | I45: =SUMIFS(Eventos!$L:$L,Eventos!$B:$B,I$39,Eventos!$K:$K,$B45,Eventos!$D:$D,$C$2) -> 0 | J45: =SUM(C45:I45) -> 0 | M45: =SUMIFS(Eventos!$G:$G,Eventos!$F:$F,$L45,Eventos!$D:$D,$C$2,Eventos!$B:$B,PANES_SEMANALES[[#ALL],[LUNES]]) -> 0 | N45: =SUMIFS(Eventos!$G:$G,Eventos!$F:$F,$L45,Eventos!$D:$D,$C$2,Eventos!$B:$B,PANES_SEMANALES[[#ALL],[MARTES]]) -> 0 | O45: =SUMIFS(Eventos!$G:$G,Eventos!$F:$F,$L45,Eventos!$D:$D,$C$2,Eventos!$B:$B,PANES_SEMANALES[[#ALL],[MIÉRCOLES]]) -> 0 | P45: =SUMIFS(Eventos!$G:$G,Eventos!$F:$F,$L45,Eventos!$D:$D,$C$2,Eventos!$B:$B,PANES_SEMANALES[[#ALL],[JUEVES]]) -> 0 | Q45: =IF(P45<>"",SUMIFS(Eventos!$G:$G,Eventos!$B:$B,Q$2,Eventos!$D:$D,$C$2,Eventos!$F:$F,$L45),"") -> 0 | R45: =SUMIFS(Eventos!$G:$G,Eventos!$F:$F,$L45,Eventos!$D:$D,$C$2,Eventos!$B:$B,PANES_SEMANALES[[#ALL],[SÁBADO]]) -> 0 | S45: =SUMIFS(Eventos!$G:$G,Eventos!$F:$F,$L45,Eventos!$D:$D,$C$2,Eventos!$B:$B,PANES_SEMANALES[[#ALL],[DOMINGO]]) -> 0 | T45: =SUM(M45:S45) -> 0
C46: =SUMIFS(Eventos!$L:$L,Eventos!$B:$B,C$39,Eventos!$K:$K,$B46,Eventos!$D:$D,$C$2) -> 0 | D46: =SUMIFS(Eventos!$L:$L,Eventos!$B:$B,D$39,Eventos!$K:$K,$B46,Eventos!$D:$D,$C$2) -> 0 | E46: =SUMIFS(Eventos!$L:$L,Eventos!$B:$B,E$39,Eventos!$K:$K,$B46,Eventos!$D:$D,$C$2) -> 0 | F46: =SUMIFS(Eventos!$L:$L,Eventos!$B:$B,F$39,Eventos!$K:$K,$B46,Eventos!$D:$D,$C$2) -> 0 | G46: =SUMIFS(Eventos!$L:$L,Eventos!$B:$B,G$39,Eventos!$K:$K,$B46,Eventos!$D:$D,$C$2) -> 0 | H46: =SUMIFS(Eventos!$L:$L,Eventos!$B:$B,H$39,Eventos!$K:$K,$B46,Eventos!$D:$D,$C$2) -> 0 | I46: =SUMIFS(Eventos!$L:$L,Eventos!$B:$B,I$39,Eventos!$K:$K,$B46,Eventos!$D:$D,$C$2) -> 0 | J46: =SUM(C46:I46) -> 0 | M46: =SUMIFS(Eventos!$G:$G,Eventos!$F:$F,$L46,Eventos!$D:$D,$C$2,Eventos!$B:$B,PANES_SEMANALES[[#ALL],[LUNES]]) -> 0 | N46: =SUMIFS(Eventos!$G:$G,Eventos!$F:$F,$L46,Eventos!$D:$D,$C$2,Eventos!$B:$B,PANES_SEMANALES[[#ALL],[MARTES]]) -> 0 | O46: =SUMIFS(Eventos!$G:$G,Eventos!$F:$F,$L46,Eventos!$D:$D,$C$2,Eventos!$B:$B,PANES_SEMANALES[[#ALL],[MIÉRCOLES]]) -> 0 | P46: =SUMIFS(Eventos!$G:$G,Eventos!$F:$F,$L46,Eventos!$D:$D,$C$2,Eventos!$B:$B,PANES_SEMANALES[[#ALL],[JUEVES]]) -> 0 | Q46: =IF(P46<>"",SUMIFS(Eventos!$G:$G,Eventos!$B:$B,Q$2,Eventos!$D:$D,$C$2,Eventos!$F:$F,$L46),"") -> 0 | R46: =SUMIFS(Eventos!$G:$G,Eventos!$F:$F,$L46,Eventos!$D:$D,$C$2,Eventos!$B:$B,PANES_SEMANALES[[#ALL],[SÁBADO]]) -> 0 | S46: =SUMIFS(Eventos!$G:$G,Eventos!$F:$F,$L46,Eventos!$D:$D,$C$2,Eventos!$B:$B,PANES_SEMANALES[[#ALL],[DOMINGO]]) -> 0 | T46: =SUM(M46:S46) -> 0
C47: =SUMIFS(Eventos!$L:$L,Eventos!$B:$B,C$39,Eventos!$K:$K,$B47,Eventos!$D:$D,$C$2) -> 0 | D47: =SUMIFS(Eventos!$L:$L,Eventos!$B:$B,D$39,Eventos!$K:$K,$B47,Eventos!$D:$D,$C$2) -> 0 | E47: =SUMIFS(Eventos!$L:$L,Eventos!$B:$B,E$39,Eventos!$K:$K,$B47,Eventos!$D:$D,$C$2) -> 0 | F47: =SUMIFS(Eventos!$L:$L,Eventos!$B:$B,F$39,Eventos!$K:$K,$B47,Eventos!$D:$D,$C$2) -> 0 | G47: =SUMIFS(Eventos!$L:$L,Eventos!$B:$B,G$39,Eventos!$K:$K,$B47,Eventos!$D:$D,$C$2) -> 0 | H47: =SUMIFS(Eventos!$L:$L,Eventos!$B:$B,H$39,Eventos!$K:$K,$B47,Eventos!$D:$D,$C$2) -> 0 | I47: =SUMIFS(Eventos!$L:$L,Eventos!$B:$B,I$39,Eventos!$K:$K,$B47,Eventos!$D:$D,$C$2) -> 0 | J47: =SUM(C47:I47) -> 0 | M47: =SUMIFS(Eventos!$G:$G,Eventos!$F:$F,$L47,Eventos!$D:$D,$C$2,Eventos!$B:$B,PANES_SEMANALES[[#ALL],[LUNES]]) -> 0 | N47: =SUMIFS(Eventos!$G:$G,Eventos!$F:$F,$L47,Eventos!$D:$D,$C$2,Eventos!$B:$B,PANES_SEMANALES[[#ALL],[MARTES]]) -> 0 | O47: =SUMIFS(Eventos!$G:$G,Eventos!$F:$F,$L47,Eventos!$D:$D,$C$2,Eventos!$B:$B,PANES_SEMANALES[[#ALL],[MIÉRCOLES]]) -> 0 | P47: =SUMIFS(Eventos!$G:$G,Eventos!$F:$F,$L47,Eventos!$D:$D,$C$2,Eventos!$B:$B,PANES_SEMANALES[[#ALL],[JUEVES]]) -> 0 | Q47: =IF(P47<>"",SUMIFS(Eventos!$G:$G,Eventos!$B:$B,Q$2,Eventos!$D:$D,$C$2,Eventos!$F:$F,$L47),"") -> 0 | R47: =SUMIFS(Eventos!$G:$G,Eventos!$F:$F,$L47,Eventos!$D:$D,$C$2,Eventos!$B:$B,PANES_SEMANALES[[#ALL],[SÁBADO]]) -> 0 | S47: =SUMIFS(Eventos!$G:$G,Eventos!$F:$F,$L47,Eventos!$D:$D,$C$2,Eventos!$B:$B,PANES_SEMANALES[[#ALL],[DOMINGO]]) -> 0 | T47: =SUM(M47:S47) -> 0
C48: =SUMIFS(Eventos!$L:$L,Eventos!$B:$B,C$39,Eventos!$K:$K,$B48,Eventos!$D:$D,$C$2) -> 0 | D48: =SUMIFS(Eventos!$L:$L,Eventos!$B:$B,D$39,Eventos!$K:$K,$B48,Eventos!$D:$D,$C$2) -> 0 | E48: =SUMIFS(Eventos!$L:$L,Eventos!$B:$B,E$39,Eventos!$K:$K,$B48,Eventos!$D:$D,$C$2) -> 0 | F48: =SUMIFS(Eventos!$L:$L,Eventos!$B:$B,F$39,Eventos!$K:$K,$B48,Eventos!$D:$D,$C$2) -> 0 | G48: =SUMIFS(Eventos!$L:$L,Eventos!$B:$B,G$39,Eventos!$K:$K,$B48,Eventos!$D:$D,$C$2) -> 0 | H48: =SUMIFS(Eventos!$L:$L,Eventos!$B:$B,H$39,Eventos!$K:$K,$B48,Eventos!$D:$D,$C$2) -> 0 | I48: =SUMIFS(Eventos!$L:$L,Eventos!$B:$B,I$39,Eventos!$K:$K,$B48,Eventos!$D:$D,$C$2) -> 0 | J48: =SUM(C48:I48) -> 0 | M48: =SUMIFS(Eventos!$G:$G,Eventos!$F:$F,$L48,Eventos!$D:$D,$C$2,Eventos!$B:$B,PANES_SEMANALES[[#ALL],[LUNES]]) -> 0 | N48: =SUMIFS(Eventos!$G:$G,Eventos!$F:$F,$L48,Eventos!$D:$D,$C$2,Eventos!$B:$B,PANES_SEMANALES[[#ALL],[MARTES]]) -> 0 | O48: =SUMIFS(Eventos!$G:$G,Eventos!$F:$F,$L48,Eventos!$D:$D,$C$2,Eventos!$B:$B,PANES_SEMANALES[[#ALL],[MIÉRCOLES]]) -> 0 | P48: =SUMIFS(Eventos!$G:$G,Eventos!$F:$F,$L48,Eventos!$D:$D,$C$2,Eventos!$B:$B,PANES_SEMANALES[[#ALL],[JUEVES]]) -> 0 | Q48: =IF(P48<>"",SUMIFS(Eventos!$G:$G,Eventos!$B:$B,Q$2,Eventos!$D:$D,$C$2,Eventos!$F:$F,$L48),"") -> 0 | R48: =SUMIFS(Eventos!$G:$G,Eventos!$F:$F,$L48,Eventos!$D:$D,$C$2,Eventos!$B:$B,PANES_SEMANALES[[#ALL],[SÁBADO]]) -> 0 | S48: =SUMIFS(Eventos!$G:$G,Eventos!$F:$F,$L48,Eventos!$D:$D,$C$2,Eventos!$B:$B,PANES_SEMANALES[[#ALL],[DOMINGO]]) -> 0 | T48: =SUM(M48:S48) -> 0
C49: =SUMIFS(Eventos!$L:$L,Eventos!$B:$B,C$39,Eventos!$K:$K,$B49,Eventos!$D:$D,$C$2) -> 0 | D49: =SUMIFS(Eventos!$L:$L,Eventos!$B:$B,D$39,Eventos!$K:$K,$B49,Eventos!$D:$D,$C$2) -> 0 | E49: =SUMIFS(Eventos!$L:$L,Eventos!$B:$B,E$39,Eventos!$K:$K,$B49,Eventos!$D:$D,$C$2) -> 0 | F49: =SUMIFS(Eventos!$L:$L,Eventos!$B:$B,F$39,Eventos!$K:$K,$B49,Eventos!$D:$D,$C$2) -> 0 | G49: =SUMIFS(Eventos!$L:$L,Eventos!$B:$B,G$39,Eventos!$K:$K,$B49,Eventos!$D:$D,$C$2) -> 0 | H49: =SUMIFS(Eventos!$L:$L,Eventos!$B:$B,H$39,Eventos!$K:$K,$B49,Eventos!$D:$D,$C$2) -> 0 | I49: =SUMIFS(Eventos!$L:$L,Eventos!$B:$B,I$39,Eventos!$K:$K,$B49,Eventos!$D:$D,$C$2) -> 0 | J49: =SUM(C49:I49) -> 0 | M49: =SUMIFS(Eventos!$G:$G,Eventos!$F:$F,$L49,Eventos!$D:$D,$C$2,Eventos!$B:$B,PANES_SEMANALES[[#ALL],[LUNES]]) -> 0 | N49: =SUMIFS(Eventos!$G:$G,Eventos!$F:$F,$L49,Eventos!$D:$D,$C$2,Eventos!$B:$B,PANES_SEMANALES[[#ALL],[MARTES]]) -> 0 | O49: =SUMIFS(Eventos!$G:$G,Eventos!$F:$F,$L49,Eventos!$D:$D,$C$2,Eventos!$B:$B,PANES_SEMANALES[[#ALL],[MIÉRCOLES]]) -> 0 | P49: =SUMIFS(Eventos!$G:$G,Eventos!$F:$F,$L49,Eventos!$D:$D,$C$2,Eventos!$B:$B,PANES_SEMANALES[[#ALL],[JUEVES]]) -> 0 | Q49: =IF(P49<>"",SUMIFS(Eventos!$G:$G,Eventos!$B:$B,Q$2,Eventos!$D:$D,$C$2,Eventos!$F:$F,$L49),"") -> 0 | R49: =SUMIFS(Eventos!$G:$G,Eventos!$F:$F,$L49,Eventos!$D:$D,$C$2,Eventos!$B:$B,PANES_SEMANALES[[#ALL],[SÁBADO]]) -> 0 | S49: =SUMIFS(Eventos!$G:$G,Eventos!$F:$F,$L49,Eventos!$D:$D,$C$2,Eventos!$B:$B,PANES_SEMANALES[[#ALL],[DOMINGO]]) -> 0 | T49: =SUM(M49:S49) -> 0
C50: =SUMIFS(Eventos!$L:$L,Eventos!$B:$B,C$39,Eventos!$K:$K,$B50,Eventos!$D:$D,$C$2) -> 0 | D50: =SUMIFS(Eventos!$L:$L,Eventos!$B:$B,D$39,Eventos!$K:$K,$B50,Eventos!$D:$D,$C$2) -> 0 | E50: =SUMIFS(Eventos!$L:$L,Eventos!$B:$B,E$39,Eventos!$K:$K,$B50,Eventos!$D:$D,$C$2) -> 0 | F50: =SUMIFS(Eventos!$L:$L,Eventos!$B:$B,F$39,Eventos!$K:$K,$B50,Eventos!$D:$D,$C$2) -> 0 | G50: =SUMIFS(Eventos!$L:$L,Eventos!$B:$B,G$39,Eventos!$K:$K,$B50,Eventos!$D:$D,$C$2) -> 0 | H50: =SUMIFS(Eventos!$L:$L,Eventos!$B:$B,H$39,Eventos!$K:$K,$B50,Eventos!$D:$D,$C$2) -> 0 | I50: =SUMIFS(Eventos!$L:$L,Eventos!$B:$B,I$39,Eventos!$K:$K,$B50,Eventos!$D:$D,$C$2) -> 0 | J50: =SUM(C50:I50) -> 0 | M50: =SUMIFS(Eventos!$G:$G,Eventos!$F:$F,$L50,Eventos!$D:$D,$C$2,Eventos!$B:$B,PANES_SEMANALES[[#ALL],[LUNES]]) -> 0 | N50: =SUMIFS(Eventos!$G:$G,Eventos!$F:$F,$L50,Eventos!$D:$D,$C$2,Eventos!$B:$B,PANES_SEMANALES[[#ALL],[MARTES]]) -> 0 | O50: =SUMIFS(Eventos!$G:$G,Eventos!$F:$F,$L50,Eventos!$D:$D,$C$2,Eventos!$B:$B,PANES_SEMANALES[[#ALL],[MIÉRCOLES]]) -> 0 | P50: =SUMIFS(Eventos!$G:$G,Eventos!$F:$F,$L50,Eventos!$D:$D,$C$2,Eventos!$B:$B,PANES_SEMANALES[[#ALL],[JUEVES]]) -> 0 | Q50: =IF(P50<>"",SUMIFS(Eventos!$G:$G,Eventos!$B:$B,Q$2,Eventos!$D:$D,$C$2,Eventos!$F:$F,$L50),"") -> 0 | R50: =SUMIFS(Eventos!$G:$G,Eventos!$F:$F,$L50,Eventos!$D:$D,$C$2,Eventos!$B:$B,PANES_SEMANALES[[#ALL],[SÁBADO]]) -> 0 | S50: =SUMIFS(Eventos!$G:$G,Eventos!$F:$F,$L50,Eventos!$D:$D,$C$2,Eventos!$B:$B,PANES_SEMANALES[[#ALL],[DOMINGO]]) -> 0 | T50: =SUM(M50:S50) -> 0
C51: =SUMIFS(Eventos!$L:$L,Eventos!$B:$B,C$39,Eventos!$K:$K,$B51,Eventos!$D:$D,$C$2) -> 0 | D51: =SUMIFS(Eventos!$L:$L,Eventos!$B:$B,D$39,Eventos!$K:$K,$B51,Eventos!$D:$D,$C$2) -> 0 | E51: =SUMIFS(Eventos!$L:$L,Eventos!$B:$B,E$39,Eventos!$K:$K,$B51,Eventos!$D:$D,$C$2) -> 0 | F51: =SUMIFS(Eventos!$L:$L,Eventos!$B:$B,F$39,Eventos!$K:$K,$B51,Eventos!$D:$D,$C$2) -> 0 | G51: =SUMIFS(Eventos!$L:$L,Eventos!$B:$B,G$39,Eventos!$K:$K,$B51,Eventos!$D:$D,$C$2) -> 0 | H51: =SUMIFS(Eventos!$L:$L,Eventos!$B:$B,H$39,Eventos!$K:$K,$B51,Eventos!$D:$D,$C$2) -> 0 | I51: =SUMIFS(Eventos!$L:$L,Eventos!$B:$B,I$39,Eventos!$K:$K,$B51,Eventos!$D:$D,$C$2) -> 0 | J51: =SUM(C51:I51) -> 0 | M51: =SUMIFS(Eventos!$G:$G,Eventos!$F:$F,$L51,Eventos!$D:$D,$C$2,Eventos!$B:$B,PANES_SEMANALES[[#ALL],[LUNES]]) -> 0 | N51: =SUMIFS(Eventos!$G:$G,Eventos!$F:$F,$L51,Eventos!$D:$D,$C$2,Eventos!$B:$B,PANES_SEMANALES[[#ALL],[MARTES]]) -> 0 | O51: =SUMIFS(Eventos!$G:$G,Eventos!$F:$F,$L51,Eventos!$D:$D,$C$2,Eventos!$B:$B,PANES_SEMANALES[[#ALL],[MIÉRCOLES]]) -> 0 | P51: =SUMIFS(Eventos!$G:$G,Eventos!$F:$F,$L51,Eventos!$D:$D,$C$2,Eventos!$B:$B,PANES_SEMANALES[[#ALL],[JUEVES]]) -> 0 | Q51: =IF(P51<>"",SUMIFS(Eventos!$G:$G,Eventos!$B:$B,Q$2,Eventos!$D:$D,$C$2,Eventos!$F:$F,$L51),"") -> 0 | R51: =SUMIFS(Eventos!$G:$G,Eventos!$F:$F,$L51,Eventos!$D:$D,$C$2,Eventos!$B:$B,PANES_SEMANALES[[#ALL],[SÁBADO]]) -> 0 | S51: =SUMIFS(Eventos!$G:$G,Eventos!$F:$F,$L51,Eventos!$D:$D,$C$2,Eventos!$B:$B,PANES_SEMANALES[[#ALL],[DOMINGO]]) -> 0 | T51: =SUM(M51:S51) -> 0
C52: =SUMIFS(Eventos!$L:$L,Eventos!$B:$B,C$39,Eventos!$K:$K,$B52,Eventos!$D:$D,$C$2) -> 0 | D52: =SUMIFS(Eventos!$L:$L,Eventos!$B:$B,D$39,Eventos!$K:$K,$B52,Eventos!$D:$D,$C$2) -> 0 | E52: =SUMIFS(Eventos!$L:$L,Eventos!$B:$B,E$39,Eventos!$K:$K,$B52,Eventos!$D:$D,$C$2) -> 0 | F52: =SUMIFS(Eventos!$L:$L,Eventos!$B:$B,F$39,Eventos!$K:$K,$B52,Eventos!$D:$D,$C$2) -> 0 | G52: =SUMIFS(Eventos!$L:$L,Eventos!$B:$B,G$39,Eventos!$K:$K,$B52,Eventos!$D:$D,$C$2) -> 0 | H52: =SUMIFS(Eventos!$L:$L,Eventos!$B:$B,H$39,Eventos!$K:$K,$B52,Eventos!$D:$D,$C$2) -> 0 | I52: =SUMIFS(Eventos!$L:$L,Eventos!$B:$B,I$39,Eventos!$K:$K,$B52,Eventos!$D:$D,$C$2) -> 0 | J52: =SUM(C52:I52) -> 0 | M52: =SUMIFS(Eventos!$G:$G,Eventos!$F:$F,$L52,Eventos!$D:$D,$C$2,Eventos!$B:$B,PANES_SEMANALES[[#ALL],[LUNES]]) -> 0 | N52: =SUMIFS(Eventos!$G:$G,Eventos!$F:$F,$L52,Eventos!$D:$D,$C$2,Eventos!$B:$B,PANES_SEMANALES[[#ALL],[MARTES]]) -> 0 | O52: =SUMIFS(Eventos!$G:$G,Eventos!$F:$F,$L52,Eventos!$D:$D,$C$2,Eventos!$B:$B,PANES_SEMANALES[[#ALL],[MIÉRCOLES]]) -> 0 | P52: =SUMIFS(Eventos!$G:$G,Eventos!$F:$F,$L52,Eventos!$D:$D,$C$2,Eventos!$B:$B,PANES_SEMANALES[[#ALL],[JUEVES]]) -> 0 | Q52: =IF(P52<>"",SUMIFS(Eventos!$G:$G,Eventos!$B:$B,Q$2,Eventos!$D:$D,$C$2,Eventos!$F:$F,$L52),"") -> 0 | R52: =SUMIFS(Eventos!$G:$G,Eventos!$F:$F,$L52,Eventos!$D:$D,$C$2,Eventos!$B:$B,PANES_SEMANALES[[#ALL],[SÁBADO]]) -> 0 | S52: =SUMIFS(Eventos!$G:$G,Eventos!$F:$F,$L52,Eventos!$D:$D,$C$2,Eventos!$B:$B,PANES_SEMANALES[[#ALL],[DOMINGO]]) -> 0 | T52: =SUM(M52:S52) -> 0
... C54: =SUMIFS(Eventos!$L:$L,Eventos!$B:$B,C$39,Eventos!$K:$K,$B54,Eventos!$D:$D,$C$2) -> 0 | D54: =SUMIFS(Eventos!$L:$L,Eventos!$B:$B,D$39,Eventos!$K:$K,$B54,Eventos!$D:$D,$C$2) -> 0 | E54: =SUMIFS(Eventos!$L:$L,Eventos!$B:$B,E$39,Eventos!$K:$K,$B54,Eventos!$D:$D,$C$2) -> 0 | F54: =SUMIFS(Eventos!$L:$L,Eventos!$B:$B,F$39,Eventos!$K:$K,$B54,Eventos!$D:$D,$C$2) -> 0 | G54: =SUMIFS(Eventos!$L:$L,Eventos!$B:$B,G$39,Eventos!$K:$K,$B54,Eventos!$D:$D,$C$2) -> 0 | H54: =SUMIFS(Eventos!$L:$L,Eventos!$B:$B,H$39,Eventos!$K:$K,$B54,Eventos!$D:$D,$C$2) -> 0 | I54: =SUMIFS(Eventos!$L:$L,Eventos!$B:$B,I$39,Eventos!$K:$K,$B54,Eventos!$D:$D,$C$2) -> 0 | J54: =SUM(C54:I54) -> 0 | M54: =SUMIFS(Eventos!$G:$G,Eventos!$F:$F,$L54,Eventos!$D:$D,$C$2,Eventos!$B:$B,PANES_SEMANALES[[#ALL],[LUNES]]) -> 0 | N54: =SUMIFS(Eventos!$G:$G,Eventos!$F:$F,$L54,Eventos!$D:$D,$C$2,Eventos!$B:$B,PANES_SEMANALES[[#ALL],[MARTES]]) -> 0 | O54: =SUMIFS(Eventos!$G:$G,Eventos!$F:$F,$L54,Eventos!$D:$D,$C$2,Eventos!$B:$B,PANES_SEMANALES[[#ALL],[MIÉRCOLES]]) -> 0 | P54: =SUMIFS(Eventos!$G:$G,Eventos!$F:$F,$L54,Eventos!$D:$D,$C$2,Eventos!$B:$B,PANES_SEMANALES[[#ALL],[JUEVES]]) -> 0 | Q54: =IF(P54<>"",SUMIFS(Eventos!$G:$G,Eventos!$B:$B,Q$2,Eventos!$D:$D,$C$2,Eventos!$F:$F,$L54),"") -> 0 | R54: =SUMIFS(Eventos!$G:$G,Eventos!$F:$F,$L54,Eventos!$D:$D,$C$2,Eventos!$B:$B,PANES_SEMANALES[[#ALL],[SÁBADO]]) -> 0 | S54: =SUMIFS(Eventos!$G:$G,Eventos!$F:$F,$L54,Eventos!$D:$D,$C$2,Eventos!$B:$B,PANES_SEMANALES[[#ALL],[DOMINGO]]) -> 0 | T54: =SUM(M54:S54) -> 0
M55: =SUMIFS(Eventos!$G:$G,Eventos!$F:$F,$L55,Eventos!$D:$D,$C$2,Eventos!$B:$B,PANES_SEMANALES[[#ALL],[LUNES]]) -> 0 | N55: =SUMIFS(Eventos!$G:$G,Eventos!$F:$F,$L55,Eventos!$D:$D,$C$2,Eventos!$B:$B,PANES_SEMANALES[[#ALL],[MARTES]]) -> 0 | O55: =SUMIFS(Eventos!$G:$G,Eventos!$F:$F,$L55,Eventos!$D:$D,$C$2,Eventos!$B:$B,PANES_SEMANALES[[#ALL],[MIÉRCOLES]]) -> 0 | P55: =SUMIFS(Eventos!$G:$G,Eventos!$F:$F,$L55,Eventos!$D:$D,$C$2,Eventos!$B:$B,PANES_SEMANALES[[#ALL],[JUEVES]]) -> 0 | Q55: =IF(P55<>"",SUMIFS(Eventos!$G:$G,Eventos!$B:$B,Q$2,Eventos!$D:$D,$C$2,Eventos!$F:$F,$L55),"") -> 0 | R55: =SUMIFS(Eventos!$G:$G,Eventos!$F:$F,$L55,Eventos!$D:$D,$C$2,Eventos!$B:$B,PANES_SEMANALES[[#ALL],[SÁBADO]]) -> 0 | S55: =SUMIFS(Eventos!$G:$G,Eventos!$F:$F,$L55,Eventos!$D:$D,$C$2,Eventos!$B:$B,PANES_SEMANALES[[#ALL],[DOMINGO]]) -> 0 | T55: =SUM(M55:S55) -> 0
M56: =SUMIFS(Eventos!$G:$G,Eventos!$F:$F,$L56,Eventos!$D:$D,$C$2,Eventos!$B:$B,PANES_SEMANALES[[#ALL],[LUNES]]) -> 0 | N56: =SUMIFS(Eventos!$G:$G,Eventos!$F:$F,$L56,Eventos!$D:$D,$C$2,Eventos!$B:$B,PANES_SEMANALES[[#ALL],[MARTES]]) -> 0 | O56: =SUMIFS(Eventos!$G:$G,Eventos!$F:$F,$L56,Eventos!$D:$D,$C$2,Eventos!$B:$B,PANES_SEMANALES[[#ALL],[MIÉRCOLES]]) -> 0 | P56: =SUMIFS(Eventos!$G:$G,Eventos!$F:$F,$L56,Eventos!$D:$D,$C$2,Eventos!$B:$B,PANES_SEMANALES[[#ALL],[JUEVES]]) -> 0 | Q56: =IF(P56<>"",SUMIFS(Eventos!$G:$G,Eventos!$B:$B,Q$2,Eventos!$D:$D,$C$2,Eventos!$F:$F,$L56),"") -> 0 | R56: =SUMIFS(Eventos!$G:$G,Eventos!$F:$F,$L56,Eventos!$D:$D,$C$2,Eventos!$B:$B,PANES_SEMANALES[[#ALL],[SÁBADO]]) -> 0 | S56: =SUMIFS(Eventos!$G:$G,Eventos!$F:$F,$L56,Eventos!$D:$D,$C$2,Eventos!$B:$B,PANES_SEMANALES[[#ALL],[DOMINGO]]) -> 0 | T56: =SUM(M56:S56) -> 0
M57: =SUMIFS(Eventos!$G:$G,Eventos!$F:$F,$L57,Eventos!$D:$D,$C$2,Eventos!$B:$B,PANES_SEMANALES[[#ALL],[LUNES]]) -> 0 | N57: =SUMIFS(Eventos!$G:$G,Eventos!$F:$F,$L57,Eventos!$D:$D,$C$2,Eventos!$B:$B,PANES_SEMANALES[[#ALL],[MARTES]]) -> 0 | O57: =SUMIFS(Eventos!$G:$G,Eventos!$F:$F,$L57,Eventos!$D:$D,$C$2,Eventos!$B:$B,PANES_SEMANALES[[#ALL],[MIÉRCOLES]]) -> 0 | P57: =SUMIFS(Eventos!$G:$G,Eventos!$F:$F,$L57,Eventos!$D:$D,$C$2,Eventos!$B:$B,PANES_SEMANALES[[#ALL],[JUEVES]]) -> 0 | Q57: =IF(P57<>"",SUMIFS(Eventos!$G:$G,Eventos!$B:$B,Q$2,Eventos!$D:$D,$C$2,Eventos!$F:$F,$L57),"") -> 0 | R57: =SUMIFS(Eventos!$G:$G,Eventos!$F:$F,$L57,Eventos!$D:$D,$C$2,Eventos!$B:$B,PANES_SEMANALES[[#ALL],[SÁBADO]]) -> 0 | S57: =SUMIFS(Eventos!$G:$G,Eventos!$F:$F,$L57,Eventos!$D:$D,$C$2,Eventos!$B:$B,PANES_SEMANALES[[#ALL],[DOMINGO]]) -> 0 | T57: =SUM(M57:S57) -> 0
M58: =SUMIFS(Eventos!$G:$G,Eventos!$F:$F,$L58,Eventos!$D:$D,$C$2,Eventos!$B:$B,PANES_SEMANALES[[#ALL],[LUNES]]) -> 0 | N58: =SUMIFS(Eventos!$G:$G,Eventos!$F:$F,$L58,Eventos!$D:$D,$C$2,Eventos!$B:$B,PANES_SEMANALES[[#ALL],[MARTES]]) -> 0 | O58: =SUMIFS(Eventos!$G:$G,Eventos!$F:$F,$L58,Eventos!$D:$D,$C$2,Eventos!$B:$B,PANES_SEMANALES[[#ALL],[MIÉRCOLES]]) -> 0 | P58: =SUMIFS(Eventos!$G:$G,Eventos!$F:$F,$L58,Eventos!$D:$D,$C$2,Eventos!$B:$B,PANES_SEMANALES[[#ALL],[JUEVES]]) -> 0 | Q58: =IF(P58<>"",SUMIFS(Eventos!$G:$G,Eventos!$B:$B,Q$2,Eventos!$D:$D,$C$2,Eventos!$F:$F,$L58),"") -> 0 | R58: =SUMIFS(Eventos!$G:$G,Eventos!$F:$F,$L58,Eventos!$D:$D,$C$2,Eventos!$B:$B,PANES_SEMANALES[[#ALL],[SÁBADO]]) -> 0 | S58: =SUMIFS(Eventos!$G:$G,Eventos!$F:$F,$L58,Eventos!$D:$D,$C$2,Eventos!$B:$B,PANES_SEMANALES[[#ALL],[DOMINGO]]) -> 0 | T58: =SUM(M58:S58) -> 0
...

Sheet Semana 23
A1: DEL SABOR | B1: Domingo
A2: Marca | B2: Día | C2: Cliente | D2: Producto | E2: Cantidad | F2: INGREDIENTES
C3: EDUARDO JEREZ | D3: HotDog Italiano | E3: 50 | F3: Pan Lengua | G3: Salchicha | H3: Tomate Picado | I3: Palta | J3: Porta HotDog
F4: 50 | G4: 50 | H4: 2000 | I4: 1750 | J4: 50
A5: EXPRESS | B5: Lunes
A6: Marca | B6: Día | C6: Cliente | D6: Producto | E6: Cantidad | F6: INGREDIENTES
C7: Brenda | D7: Pop corn | E7: 150 | F7: Cucurucho | G7: Azúcar | H7: Maíz | I7: Aceite
F8: 150 | G8: 18000 | H8: 30000 | I8: 13500
D9: Operador extra | E9: 1
A11: EXPRESS | B11: Miércoles
A12: Marca | B12: Día | C12: Cliente | D12: Producto | E12: Cantidad | F12: INGREDIENTES
C13: FRANCISCA ANABALÓN | D13: Mechada Italiana | E13: 40 | F13: Pan Brioche | G13: Mechada Vacuno | H13: Tomate Laminado | I13: Palta | J13: Plato Redondo
F14: 40 | G14: 4000 | H14: 40 | I14: 1400 | J14: 40
D15: As Luco | E15: 40 | F15: Pan Lengua | G15: Vacuno | H15: Queso | I15: Porta HotDog
F16: 40 | G16: 4000 | H16: 40 | I16: 40
A17: GOURMET | B17: Miércoles
A18: Marca | B18: Día | C18: Cliente | D18: Producto | E18: Cantidad | F18: INGREDIENTES
C19: PAOLA GODOY | D19: Hot Dog Italiano | E19: 98 | F19: Pan Lengua | G19: Salchicha | H19: Tomate Picado | I19: Palta | J19: Porta HotDog
F20: 98 | G20: 98 | H20: 3920 | I20: 3430 | J20: 98
A21: EXPRESS | B21: Jueves
A22: Marca | B22: Día | C22: Cliente | D22: Producto | E22: Cantidad | F22: INGREDIENTES
C23: DANIELA SALTRON | D23: Hamburguesas clásicas | E23: 50 | F23: Pan Brioche | G23: Hamburguesa | H23: Tomate Laminado | I23: Queso | J23: Lechuga | K23: Pepinillos | L23: Plato Redondo
F24: 50 | G24: 50 | H24: 50 | I24: 50 | J24: 1000 | K24: 500 | L24: 50
A25: GOURMET | B25: Viernes
A26: Marca | B26: Día | C26: Cliente | D26: Producto | E26: Cantidad | F26: INGREDIENTES
C27: MARIA MARCELA SABUCEO | D27: Hamburguesa Gourmet | E27: 20 | F27: Pan Brioche | G27: Hamburguesa Smash | H27: Tomate Laminado | I27: Queso | J27: Lechuga | K27: Cebolla Caramelizada | L27: Ají Verde | M27: Papas Hilo | N27: Salsa Americana | O27: Plato Redondo
F28: 20 | G28: 2000 | H28: 20 | I28: 20 | J28: 400 | K28: 400 | L28: 200 | M28: 200 | N28: 200 | O28: 20
D29: Churrasco Gourmet | E29: 20 | F29: Pan Brioche | G29: Vacuno | H29: Tomate Laminado | I29: Lechuga | J29: Cebolla Caramelizada | K29: Chucrut | L29: Ají Verde | M29: Salsa Americana | N29: Plato Redondo
F30: 20 | G30: 2000 | H30: 20 | I30: 400 | J30: 400 | K30: 200 | L30: 200 | M30: 200 | N30: 20
A31: GOURMET | B31: Viernes
A32: Marca | B32: Día | C32: Cliente | D32: Producto | E32: Cantidad | F32: INGREDIENTES
C33: ALFONSO BELANDRIA | D33: Churrasco Italiano | E33: 50 | F33: Pan Brioche | G33: Vacuno | H33: Tomate Laminado | I33: Palta | J33: Plato Redondo
F34: 50 | G34: 5000 | H34: 50 | I34: 1750 | J34: 50
A35: CAMALEON | B35: Sábado
A36: Marca | B36: Día | C36: Cliente | D36: Producto | E36: Cantidad | F36: INGREDIENTES
C37: MARÍA FERNANDA NOULDON | D37: HotDog Italiano | E37: 40 | F37: Pan Lengua | G37: Salchicha | H37: Tomate Picado | I37: Palta | J37: Porta HotDog
F38: 40 | G38: 40 | H38: 1600 | I38: 1400 | J38: 40
A39: DEL SABOR | B39: Sábado
A40: Marca | B40: Día | C40: Cliente | D40: Producto | E40: Cantidad | F40: INGREDIENTES
C41: DANIEL VALENZUELA | D41: Churrasco Italiano | E41: 90 | F41: Pan Brioche | G41: Vacuno | H41: Tomate Laminado | I41: Palta | J41: Plato Redondo
...

Sheet Semana 22
A1: CAMALEON | B1: Domingo
A2: Marca | B2: Día | C2: Cliente | D2: Producto | E2: Cantidad | F2: INGREDIENTES
C3: LIDIA SANDOVAL | D3: HotDog Italiano | E3: 60
A5: GOURMET | B5: Lunes
A6: Marca | B6: Día | C6: Cliente | D6: Producto | E6: Cantidad | F6: INGREDIENTES
C7: ALEJANDRA SÁEZ | D7: Hot Dog Italiano | E7: 150 | F7: Pan Lengua | G7: Salchicha | H7: Tomate Picado | I7: Palta | J7: Porta HotDog
F8: 150 | G8: 150 | H8: 6000 | I8: 5250 | J8: 150
A9: GOURMET | B9: Lunes
A10: Marca | B10: Día | C10: Cliente | D10: Producto | E10: Cantidad | F10: INGREDIENTES
C11: PAOLA GODOY | D11: Churrasco Italiano | E11: 350 | F11: Pan Brioche | G11: Vacuno | H11: Tomate Laminado | I11: Palta | J11: Plato Redondo
F12: 350 | G12: 35000 | H12: 350 | I12: 12250 | J12: 350
A13: GOURMET | B13: Martes
A14: Marca | B14: Día | C14: Cliente | D14: Producto | E14: Cantidad | F14: INGREDIENTES
C15: NATALIA AGUILERA | D15: Chocolate Caliente y decoración | E15: 108
D17: Cafe Caliente | E17: 72
D19: Chocolate Caliente y decoración | E19: 69
D21: Cafe Caliente | E21: 46
D23: Montaje | E23: 1
D25: Traslado | E25: 1
A27: GOURMET | B27: Miércoles
A28: Marca | B28: Día | C28: Cliente | D28: Producto | E28: Cantidad | F28: INGREDIENTES
C29: RODRIGO TAPIA | D29: Hot Dog Italiano | E29: 1025 | F29: Pan Lengua | G29: Salchicha | H29: Tomate Picado | I29: Palta | J29: Porta HotDog
F30: 1025 | G30: 1025 | H30: 41000 | I30: 35875 | J30: 1025
D31: Hot Dog Italiano Veggie | E31: 25
A33: GOURMET | B33: Miércoles
A34: Marca | B34: Día | C34: Cliente | D34: Producto | E34: Cantidad | F34: INGREDIENTES
C35: NATALIA AGUILERA | D35: Chocolate Caliente y decoración | E35: 57
D37: Cafe Caliente | E37: 38
A39: GOURMET | B39: Miércoles
A40: Marca | B40: Día | C40: Cliente | D40: Producto | E40: Cantidad | F40: INGREDIENTES
C41: JAVIERA QUIJANO | D41: Hamburguesa Gourmet | E41: 60 | F41: Pan Brioche | G41: Hamburguesa Smash | H41: Tomate Laminado | I41: Queso | J41: Lechuga | K41: Cebolla Caramelizada | L41: Ají Verde | M41: Papas Hilo | N41: Salsa Americana | O41: Plato Redondo
F42: 60 | G42: 6000 | H42: 60 | I42: 60 | J42: 1200 | K42: 1200 | L42: 600 | M42: 600 | N42: 600 | O42: 60
D43: Hamburguesa Italiana | E43: 60 | F43: Pan Brioche | G43: Hamburguesa | H43: Tomate Laminado | I43: Palta | J43: Plato Redondo
F44: 60 | G44: 60 | H44: 60 | I44: 2100 | J44: 60
D45: Hamburguesa Gourmet Veggie | E45: 3
D47: Hamburguesa Clasica Veggie | E47: 3
A49: GOURMET | B49: Miércoles
A50: Marca | B50: Día | C50: Cliente | D50: Producto | E50: Cantidad | F50: INGREDIENTES
C51: PAOLA GODOY | D51: Hot Dog Italiano | E51: 138 | F51: Pan Lengua | G51: Salchicha | H51: Tomate Picado | I51: Palta | J51: Porta HotDog
F52: 138 | G52: 138 | H52: 5520 | I52: 4830 | J52: 138
...

Sheet Semana 17
B1: Miércoles
A2: Marca | B2: Día | C2: Cliente | D2: Producto | E2: Cantidad | F2: INGREDIENTES
C3: CAMILA BONELLI | D3: Hamburguesa Italiana | E3: 40 | F3: Pan Brioche | G3: Hamburguesa | H3: Tomate Laminado | I3: Palta | J3: Plato Redondo
F4: 40 | G4: 40 | H4: 40 | I4: 1400 | J4: 40
D5: Mini Burger Italiana | E5: 20 | F5: Pan Amasado Mini | G5: Hamburguesa Smash | H5: Tomate Laminado | I5: Palta | J5: Plato Redondo
F6: 20 | G6: 1200 | H6: 20 | I6: 400 | J6: 20
B7: Viernes
A8: Marca | B8: Día | C8: Cliente | D8: Producto | E8: Cantidad | F8: INGREDIENTES
C9: KAREN PIZARRO | D9: As Italiano | E9: 40 | F9: Pan Lengua | G9: Vacuno | H9: Tomate Picado | I9: Palta | J9: Porta HotDog
F10: 40 | G10: 4000 | H10: 1600 | I10: 1400 | J10: 40
D11: Hamburguesa Italiana | E11: 40 | F11: Pan Brioche | G11: Hamburguesa | H11: Tomate Laminado | I11: Palta | J11: Plato Redondo
F12: 40 | G12: 40 | H12: 40 | I12: 1400 | J12: 40
B13: Viernes
A14: Marca | B14: Día | C14: Cliente | D14: Producto | E14: Cantidad | F14: INGREDIENTES
